[2024-05-29T13:17:15.444+0000] {local_task_job_runner.py:120} INFO - ::group::Pre task execution logs
[2024-05-29T13:17:15.495+0000] {taskinstance.py:2076} INFO - Dependencies all met for dep_context=non-requeueable deps ti=<TaskInstance: check_send_status_dag.check_status scheduled__2023-01-01T12:50:00+00:00 [queued]>
[2024-05-29T13:17:15.515+0000] {taskinstance.py:2076} INFO - Dependencies all met for dep_context=requeueable deps ti=<TaskInstance: check_send_status_dag.check_status scheduled__2023-01-01T12:50:00+00:00 [queued]>
[2024-05-29T13:17:15.516+0000] {taskinstance.py:2306} INFO - Starting attempt 1 of 2
[2024-05-29T13:17:15.583+0000] {taskinstance.py:2330} INFO - Executing <Task(PythonOperator): check_status> on 2023-01-01 12:50:00+00:00
[2024-05-29T13:17:15.588+0000] {standard_task_runner.py:63} INFO - Started process 866 to run task
[2024-05-29T13:17:15.591+0000] {standard_task_runner.py:90} INFO - Running: ['airflow', 'tasks', 'run', 'check_send_status_dag', 'check_status', 'scheduled__2023-01-01T12:50:00+00:00', '--job-id', '156', '--raw', '--subdir', 'DAGS_FOLDER/check_send_status_dag.py', '--cfg-path', '/tmp/tmp41xn1l73']
[2024-05-29T13:17:15.594+0000] {standard_task_runner.py:91} INFO - Job 156: Subtask check_status
[2024-05-29T13:17:15.796+0000] {task_command.py:426} INFO - Running <TaskInstance: check_send_status_dag.check_status scheduled__2023-01-01T12:50:00+00:00 [running]> on host f708138922bb
[2024-05-29T13:17:16.090+0000] {taskinstance.py:2648} INFO - Exporting env vars: AIRFLOW_CTX_DAG_OWNER='airflow' AIRFLOW_CTX_DAG_ID='check_send_status_dag' AIRFLOW_CTX_TASK_ID='check_status' AIRFLOW_CTX_EXECUTION_DATE='2023-01-01T12:50:00+00:00' AIRFLOW_CTX_TRY_NUMBER='1' AIRFLOW_CTX_DAG_RUN_ID='scheduled__2023-01-01T12:50:00+00:00'
[2024-05-29T13:17:16.092+0000] {taskinstance.py:430} INFO - ::endgroup::
[2024-05-29T13:17:16.134+0000] {check_send_status_dag.py:15} ERROR - Error fetching status: 500 Server Error: INTERNAL SERVER ERROR for url: http://flask:5000/check_send_status
[2024-05-29T13:17:16.135+0000] {taskinstance.py:441} INFO - ::group::Post task execution logs
[2024-05-29T13:17:16.136+0000] {taskinstance.py:2905} ERROR - Task failed with exception
Traceback (most recent call last):
  File "/home/airflow/.local/lib/python3.12/site-packages/airflow/models/taskinstance.py", line 465, in _execute_task
    result = _execute_callable(context=context, **execute_callable_kwargs)
             ^^^^^^^^^^^^^^^^^^^^^^^^^^^^^^^^^^^^^^^^^^^^^^^^^^^^^^^^^^^^^
  File "/home/airflow/.local/lib/python3.12/site-packages/airflow/models/taskinstance.py", line 432, in _execute_callable
    return execute_callable(context=context, **execute_callable_kwargs)
           ^^^^^^^^^^^^^^^^^^^^^^^^^^^^^^^^^^^^^^^^^^^^^^^^^^^^^^^^^^^^
  File "/home/airflow/.local/lib/python3.12/site-packages/airflow/models/baseoperator.py", line 400, in wrapper
    return func(self, *args, **kwargs)
           ^^^^^^^^^^^^^^^^^^^^^^^^^^^
  File "/home/airflow/.local/lib/python3.12/site-packages/airflow/operators/python.py", line 235, in execute
    return_value = self.execute_callable()
                   ^^^^^^^^^^^^^^^^^^^^^^^
  File "/home/airflow/.local/lib/python3.12/site-packages/airflow/operators/python.py", line 252, in execute_callable
    return self.python_callable(*self.op_args, **self.op_kwargs)
           ^^^^^^^^^^^^^^^^^^^^^^^^^^^^^^^^^^^^^^^^^^^^^^^^^^^^^
  File "/opt/airflow/dags/check_send_status_dag.py", line 11, in check_send_status
    response.raise_for_status()
  File "/home/airflow/.local/lib/python3.12/site-packages/requests/models.py", line 1021, in raise_for_status
    raise HTTPError(http_error_msg, response=self)
requests.exceptions.HTTPError: 500 Server Error: INTERNAL SERVER ERROR for url: http://flask:5000/check_send_status
[2024-05-29T13:17:16.172+0000] {taskinstance.py:1206} INFO - Marking task as UP_FOR_RETRY. dag_id=check_send_status_dag, task_id=check_status, run_id=scheduled__2023-01-01T12:50:00+00:00, execution_date=20230101T125000, start_date=20240529T131715, end_date=20240529T131716
[2024-05-29T13:17:16.220+0000] {standard_task_runner.py:110} ERROR - Failed to execute job 156 for task check_status (500 Server Error: INTERNAL SERVER ERROR for url: http://flask:5000/check_send_status; 866)
[2024-05-29T13:17:16.250+0000] {local_task_job_runner.py:240} INFO - Task exited with return code 1
[2024-05-29T13:17:16.278+0000] {taskinstance.py:3498} INFO - 0 downstream tasks scheduled from follow-on schedule check
[2024-05-29T13:17:16.280+0000] {local_task_job_runner.py:222} INFO - ::endgroup::
[2024-05-29T15:49:05.259+0000] {local_task_job_runner.py:120} INFO - ::group::Pre task execution logs
[2024-05-29T15:49:05.302+0000] {taskinstance.py:2076} INFO - Dependencies all met for dep_context=non-requeueable deps ti=<TaskInstance: check_send_status_dag.check_status scheduled__2023-01-01T12:50:00+00:00 [queued]>
[2024-05-29T15:49:05.318+0000] {taskinstance.py:2076} INFO - Dependencies all met for dep_context=requeueable deps ti=<TaskInstance: check_send_status_dag.check_status scheduled__2023-01-01T12:50:00+00:00 [queued]>
[2024-05-29T15:49:05.318+0000] {taskinstance.py:2306} INFO - Starting attempt 1 of 2
[2024-05-29T15:49:05.363+0000] {taskinstance.py:2330} INFO - Executing <Task(PythonOperator): check_status> on 2023-01-01 12:50:00+00:00
[2024-05-29T15:49:05.368+0000] {standard_task_runner.py:63} INFO - Started process 325 to run task
[2024-05-29T15:49:05.371+0000] {standard_task_runner.py:90} INFO - Running: ['airflow', 'tasks', 'run', 'check_send_status_dag', 'check_status', 'scheduled__2023-01-01T12:50:00+00:00', '--job-id', '142', '--raw', '--subdir', 'DAGS_FOLDER/check_send_status_dag.py', '--cfg-path', '/tmp/tmpvu9dwpzd']
[2024-05-29T15:49:05.373+0000] {standard_task_runner.py:91} INFO - Job 142: Subtask check_status
[2024-05-29T15:49:05.475+0000] {task_command.py:426} INFO - Running <TaskInstance: check_send_status_dag.check_status scheduled__2023-01-01T12:50:00+00:00 [running]> on host f708138922bb
[2024-05-29T15:49:05.686+0000] {taskinstance.py:2648} INFO - Exporting env vars: AIRFLOW_CTX_DAG_OWNER='airflow' AIRFLOW_CTX_DAG_ID='check_send_status_dag' AIRFLOW_CTX_TASK_ID='check_status' AIRFLOW_CTX_EXECUTION_DATE='2023-01-01T12:50:00+00:00' AIRFLOW_CTX_TRY_NUMBER='1' AIRFLOW_CTX_DAG_RUN_ID='scheduled__2023-01-01T12:50:00+00:00'
[2024-05-29T15:49:05.687+0000] {taskinstance.py:430} INFO - ::endgroup::
[2024-05-29T15:49:05.719+0000] {check_send_status_dag.py:15} ERROR - Error fetching status: 500 Server Error: INTERNAL SERVER ERROR for url: http://flask:5000/check_send_status
[2024-05-29T15:49:05.721+0000] {taskinstance.py:441} INFO - ::group::Post task execution logs
[2024-05-29T15:49:05.730+0000] {taskinstance.py:2905} ERROR - Task failed with exception
Traceback (most recent call last):
  File "/home/airflow/.local/lib/python3.12/site-packages/airflow/models/taskinstance.py", line 465, in _execute_task
    result = _execute_callable(context=context, **execute_callable_kwargs)
             ^^^^^^^^^^^^^^^^^^^^^^^^^^^^^^^^^^^^^^^^^^^^^^^^^^^^^^^^^^^^^
  File "/home/airflow/.local/lib/python3.12/site-packages/airflow/models/taskinstance.py", line 432, in _execute_callable
    return execute_callable(context=context, **execute_callable_kwargs)
           ^^^^^^^^^^^^^^^^^^^^^^^^^^^^^^^^^^^^^^^^^^^^^^^^^^^^^^^^^^^^
  File "/home/airflow/.local/lib/python3.12/site-packages/airflow/models/baseoperator.py", line 400, in wrapper
    return func(self, *args, **kwargs)
           ^^^^^^^^^^^^^^^^^^^^^^^^^^^
  File "/home/airflow/.local/lib/python3.12/site-packages/airflow/operators/python.py", line 235, in execute
    return_value = self.execute_callable()
                   ^^^^^^^^^^^^^^^^^^^^^^^
  File "/home/airflow/.local/lib/python3.12/site-packages/airflow/operators/python.py", line 252, in execute_callable
    return self.python_callable(*self.op_args, **self.op_kwargs)
           ^^^^^^^^^^^^^^^^^^^^^^^^^^^^^^^^^^^^^^^^^^^^^^^^^^^^^
  File "/opt/airflow/dags/check_send_status_dag.py", line 11, in check_send_status
    response.raise_for_status()
  File "/home/airflow/.local/lib/python3.12/site-packages/requests/models.py", line 1021, in raise_for_status
    raise HTTPError(http_error_msg, response=self)
requests.exceptions.HTTPError: 500 Server Error: INTERNAL SERVER ERROR for url: http://flask:5000/check_send_status
[2024-05-29T15:49:05.751+0000] {taskinstance.py:1206} INFO - Marking task as UP_FOR_RETRY. dag_id=check_send_status_dag, task_id=check_status, run_id=scheduled__2023-01-01T12:50:00+00:00, execution_date=20230101T125000, start_date=20240529T154905, end_date=20240529T154905
[2024-05-29T15:49:05.790+0000] {standard_task_runner.py:110} ERROR - Failed to execute job 142 for task check_status (500 Server Error: INTERNAL SERVER ERROR for url: http://flask:5000/check_send_status; 325)
[2024-05-29T15:49:05.827+0000] {local_task_job_runner.py:240} INFO - Task exited with return code 1
[2024-05-29T15:49:05.852+0000] {taskinstance.py:3498} INFO - 0 downstream tasks scheduled from follow-on schedule check
[2024-05-29T15:49:05.855+0000] {local_task_job_runner.py:222} INFO - ::endgroup::
