[2024-05-29T13:09:00.679+0000] {local_task_job_runner.py:120} INFO - ::group::Pre task execution logs
[2024-05-29T13:09:00.736+0000] {taskinstance.py:2076} INFO - Dependencies all met for dep_context=non-requeueable deps ti=<TaskInstance: check_send_status_dag.check_status scheduled__2023-01-01T08:10:00+00:00 [queued]>
[2024-05-29T13:09:00.768+0000] {taskinstance.py:2076} INFO - Dependencies all met for dep_context=requeueable deps ti=<TaskInstance: check_send_status_dag.check_status scheduled__2023-01-01T08:10:00+00:00 [queued]>
[2024-05-29T13:09:00.769+0000] {taskinstance.py:2306} INFO - Starting attempt 2 of 2
[2024-05-29T13:09:00.836+0000] {taskinstance.py:2330} INFO - Executing <Task(PythonOperator): check_status> on 2023-01-01 08:10:00+00:00
[2024-05-29T13:09:00.845+0000] {standard_task_runner.py:63} INFO - Started process 652 to run task
[2024-05-29T13:09:00.848+0000] {standard_task_runner.py:90} INFO - Running: ['airflow', 'tasks', 'run', 'check_send_status_dag', 'check_status', 'scheduled__2023-01-01T08:10:00+00:00', '--job-id', '116', '--raw', '--subdir', 'DAGS_FOLDER/check_send_status_dag.py', '--cfg-path', '/tmp/tmpxg6m8c1u']
[2024-05-29T13:09:00.850+0000] {standard_task_runner.py:91} INFO - Job 116: Subtask check_status
[2024-05-29T13:09:00.962+0000] {task_command.py:426} INFO - Running <TaskInstance: check_send_status_dag.check_status scheduled__2023-01-01T08:10:00+00:00 [running]> on host f708138922bb
[2024-05-29T13:09:01.124+0000] {taskinstance.py:2648} INFO - Exporting env vars: AIRFLOW_CTX_DAG_OWNER='airflow' AIRFLOW_CTX_DAG_ID='check_send_status_dag' AIRFLOW_CTX_TASK_ID='check_status' AIRFLOW_CTX_EXECUTION_DATE='2023-01-01T08:10:00+00:00' AIRFLOW_CTX_TRY_NUMBER='2' AIRFLOW_CTX_DAG_RUN_ID='scheduled__2023-01-01T08:10:00+00:00'
[2024-05-29T13:09:01.125+0000] {taskinstance.py:430} INFO - ::endgroup::
[2024-05-29T13:09:01.143+0000] {check_send_status_dag.py:15} ERROR - Error fetching status: HTTPConnectionPool(host='127.0.0.1', port=5000): Max retries exceeded with url: /check_send_status (Caused by NewConnectionError('<urllib3.connection.HTTPConnection object at 0x7f1ff7481d60>: Failed to establish a new connection: [Errno 111] Connection refused'))
[2024-05-29T13:09:01.144+0000] {taskinstance.py:441} INFO - ::group::Post task execution logs
[2024-05-29T13:09:01.145+0000] {taskinstance.py:2905} ERROR - Task failed with exception
Traceback (most recent call last):
  File "/home/airflow/.local/lib/python3.12/site-packages/urllib3/connection.py", line 198, in _new_conn
    sock = connection.create_connection(
           ^^^^^^^^^^^^^^^^^^^^^^^^^^^^^
  File "/home/airflow/.local/lib/python3.12/site-packages/urllib3/util/connection.py", line 85, in create_connection
    raise err
  File "/home/airflow/.local/lib/python3.12/site-packages/urllib3/util/connection.py", line 73, in create_connection
    sock.connect(sa)
ConnectionRefusedError: [Errno 111] Connection refused

The above exception was the direct cause of the following exception:

Traceback (most recent call last):
  File "/home/airflow/.local/lib/python3.12/site-packages/urllib3/connectionpool.py", line 793, in urlopen
    response = self._make_request(
               ^^^^^^^^^^^^^^^^^^^
  File "/home/airflow/.local/lib/python3.12/site-packages/urllib3/connectionpool.py", line 496, in _make_request
    conn.request(
  File "/home/airflow/.local/lib/python3.12/site-packages/urllib3/connection.py", line 400, in request
    self.endheaders()
  File "/usr/local/lib/python3.12/http/client.py", line 1331, in endheaders
    self._send_output(message_body, encode_chunked=encode_chunked)
  File "/usr/local/lib/python3.12/http/client.py", line 1091, in _send_output
    self.send(msg)
  File "/usr/local/lib/python3.12/http/client.py", line 1035, in send
    self.connect()
  File "/home/airflow/.local/lib/python3.12/site-packages/urllib3/connection.py", line 238, in connect
    self.sock = self._new_conn()
                ^^^^^^^^^^^^^^^^
  File "/home/airflow/.local/lib/python3.12/site-packages/urllib3/connection.py", line 213, in _new_conn
    raise NewConnectionError(
urllib3.exceptions.NewConnectionError: <urllib3.connection.HTTPConnection object at 0x7f1ff7481d60>: Failed to establish a new connection: [Errno 111] Connection refused

The above exception was the direct cause of the following exception:

Traceback (most recent call last):
  File "/home/airflow/.local/lib/python3.12/site-packages/requests/adapters.py", line 486, in send
    resp = conn.urlopen(
           ^^^^^^^^^^^^^
  File "/home/airflow/.local/lib/python3.12/site-packages/urllib3/connectionpool.py", line 847, in urlopen
    retries = retries.increment(
              ^^^^^^^^^^^^^^^^^^
  File "/home/airflow/.local/lib/python3.12/site-packages/urllib3/util/retry.py", line 515, in increment
    raise MaxRetryError(_pool, url, reason) from reason  # type: ignore[arg-type]
    ^^^^^^^^^^^^^^^^^^^^^^^^^^^^^^^^^^^^^^^^^^^^^^^^^^^
urllib3.exceptions.MaxRetryError: HTTPConnectionPool(host='127.0.0.1', port=5000): Max retries exceeded with url: /check_send_status (Caused by NewConnectionError('<urllib3.connection.HTTPConnection object at 0x7f1ff7481d60>: Failed to establish a new connection: [Errno 111] Connection refused'))

During handling of the above exception, another exception occurred:

Traceback (most recent call last):
  File "/home/airflow/.local/lib/python3.12/site-packages/airflow/models/taskinstance.py", line 465, in _execute_task
    result = _execute_callable(context=context, **execute_callable_kwargs)
             ^^^^^^^^^^^^^^^^^^^^^^^^^^^^^^^^^^^^^^^^^^^^^^^^^^^^^^^^^^^^^
  File "/home/airflow/.local/lib/python3.12/site-packages/airflow/models/taskinstance.py", line 432, in _execute_callable
    return execute_callable(context=context, **execute_callable_kwargs)
           ^^^^^^^^^^^^^^^^^^^^^^^^^^^^^^^^^^^^^^^^^^^^^^^^^^^^^^^^^^^^
  File "/home/airflow/.local/lib/python3.12/site-packages/airflow/models/baseoperator.py", line 400, in wrapper
    return func(self, *args, **kwargs)
           ^^^^^^^^^^^^^^^^^^^^^^^^^^^
  File "/home/airflow/.local/lib/python3.12/site-packages/airflow/operators/python.py", line 235, in execute
    return_value = self.execute_callable()
                   ^^^^^^^^^^^^^^^^^^^^^^^
  File "/home/airflow/.local/lib/python3.12/site-packages/airflow/operators/python.py", line 252, in execute_callable
    return self.python_callable(*self.op_args, **self.op_kwargs)
           ^^^^^^^^^^^^^^^^^^^^^^^^^^^^^^^^^^^^^^^^^^^^^^^^^^^^^
  File "/opt/airflow/dags/check_send_status_dag.py", line 10, in check_send_status
    response = requests.get("http://127.0.0.1:5000/check_send_status")
               ^^^^^^^^^^^^^^^^^^^^^^^^^^^^^^^^^^^^^^^^^^^^^^^^^^^^^^^
  File "/home/airflow/.local/lib/python3.12/site-packages/requests/api.py", line 73, in get
    return request("get", url, params=params, **kwargs)
           ^^^^^^^^^^^^^^^^^^^^^^^^^^^^^^^^^^^^^^^^^^^^
  File "/home/airflow/.local/lib/python3.12/site-packages/requests/api.py", line 59, in request
    return session.request(method=method, url=url, **kwargs)
           ^^^^^^^^^^^^^^^^^^^^^^^^^^^^^^^^^^^^^^^^^^^^^^^^^
  File "/home/airflow/.local/lib/python3.12/site-packages/requests/sessions.py", line 589, in request
    resp = self.send(prep, **send_kwargs)
           ^^^^^^^^^^^^^^^^^^^^^^^^^^^^^^
  File "/home/airflow/.local/lib/python3.12/site-packages/requests/sessions.py", line 703, in send
    r = adapter.send(request, **kwargs)
        ^^^^^^^^^^^^^^^^^^^^^^^^^^^^^^^
  File "/home/airflow/.local/lib/python3.12/site-packages/requests/adapters.py", line 519, in send
    raise ConnectionError(e, request=request)
requests.exceptions.ConnectionError: HTTPConnectionPool(host='127.0.0.1', port=5000): Max retries exceeded with url: /check_send_status (Caused by NewConnectionError('<urllib3.connection.HTTPConnection object at 0x7f1ff7481d60>: Failed to establish a new connection: [Errno 111] Connection refused'))
[2024-05-29T13:09:01.168+0000] {taskinstance.py:1206} INFO - Marking task as FAILED. dag_id=check_send_status_dag, task_id=check_status, run_id=scheduled__2023-01-01T08:10:00+00:00, execution_date=20230101T081000, start_date=20240529T130900, end_date=20240529T130901
[2024-05-29T13:09:01.211+0000] {standard_task_runner.py:110} ERROR - Failed to execute job 116 for task check_status (HTTPConnectionPool(host='127.0.0.1', port=5000): Max retries exceeded with url: /check_send_status (Caused by NewConnectionError('<urllib3.connection.HTTPConnection object at 0x7f1ff7481d60>: Failed to establish a new connection: [Errno 111] Connection refused')); 652)
[2024-05-29T13:09:01.222+0000] {local_task_job_runner.py:240} INFO - Task exited with return code 1
[2024-05-29T13:09:01.250+0000] {taskinstance.py:3498} INFO - 0 downstream tasks scheduled from follow-on schedule check
[2024-05-29T13:09:01.253+0000] {local_task_job_runner.py:222} INFO - ::endgroup::
[2024-05-29T15:11:33.802+0000] {local_task_job_runner.py:120} INFO - ::group::Pre task execution logs
[2024-05-29T15:11:33.853+0000] {taskinstance.py:2076} INFO - Dependencies all met for dep_context=non-requeueable deps ti=<TaskInstance: check_send_status_dag.check_status scheduled__2023-01-01T08:10:00+00:00 [queued]>
[2024-05-29T15:11:33.873+0000] {taskinstance.py:2076} INFO - Dependencies all met for dep_context=requeueable deps ti=<TaskInstance: check_send_status_dag.check_status scheduled__2023-01-01T08:10:00+00:00 [queued]>
[2024-05-29T15:11:33.874+0000] {taskinstance.py:2306} INFO - Starting attempt 2 of 2
[2024-05-29T15:11:33.920+0000] {taskinstance.py:2330} INFO - Executing <Task(PythonOperator): check_status> on 2023-01-01 08:10:00+00:00
[2024-05-29T15:11:33.926+0000] {standard_task_runner.py:63} INFO - Started process 79 to run task
[2024-05-29T15:11:33.931+0000] {standard_task_runner.py:90} INFO - Running: ['airflow', 'tasks', 'run', 'check_send_status_dag', 'check_status', 'scheduled__2023-01-01T08:10:00+00:00', '--job-id', '96', '--raw', '--subdir', 'DAGS_FOLDER/check_send_status_dag.py', '--cfg-path', '/tmp/tmp6jdubo28']
[2024-05-29T15:11:33.935+0000] {standard_task_runner.py:91} INFO - Job 96: Subtask check_status
[2024-05-29T15:11:34.049+0000] {task_command.py:426} INFO - Running <TaskInstance: check_send_status_dag.check_status scheduled__2023-01-01T08:10:00+00:00 [running]> on host f708138922bb
[2024-05-29T15:11:34.236+0000] {taskinstance.py:2648} INFO - Exporting env vars: AIRFLOW_CTX_DAG_OWNER='airflow' AIRFLOW_CTX_DAG_ID='check_send_status_dag' AIRFLOW_CTX_TASK_ID='check_status' AIRFLOW_CTX_EXECUTION_DATE='2023-01-01T08:10:00+00:00' AIRFLOW_CTX_TRY_NUMBER='2' AIRFLOW_CTX_DAG_RUN_ID='scheduled__2023-01-01T08:10:00+00:00'
[2024-05-29T15:11:34.239+0000] {taskinstance.py:430} INFO - ::endgroup::
[2024-05-29T15:11:37.600+0000] {check_send_status_dag.py:15} ERROR - Error fetching status: HTTPConnectionPool(host='flask', port=5000): Max retries exceeded with url: /check_send_status (Caused by NameResolutionError("<urllib3.connection.HTTPConnection object at 0x7fc610c98290>: Failed to resolve 'flask' ([Errno -2] Name or service not known)"))
[2024-05-29T15:11:37.603+0000] {taskinstance.py:441} INFO - ::group::Post task execution logs
[2024-05-29T15:11:37.605+0000] {taskinstance.py:2905} ERROR - Task failed with exception
Traceback (most recent call last):
  File "/home/airflow/.local/lib/python3.12/site-packages/urllib3/connection.py", line 198, in _new_conn
    sock = connection.create_connection(
           ^^^^^^^^^^^^^^^^^^^^^^^^^^^^^
  File "/home/airflow/.local/lib/python3.12/site-packages/urllib3/util/connection.py", line 60, in create_connection
    for res in socket.getaddrinfo(host, port, family, socket.SOCK_STREAM):
               ^^^^^^^^^^^^^^^^^^^^^^^^^^^^^^^^^^^^^^^^^^^^^^^^^^^^^^^^^^
  File "/usr/local/lib/python3.12/socket.py", line 963, in getaddrinfo
    for res in _socket.getaddrinfo(host, port, family, type, proto, flags):
               ^^^^^^^^^^^^^^^^^^^^^^^^^^^^^^^^^^^^^^^^^^^^^^^^^^^^^^^^^^^
socket.gaierror: [Errno -2] Name or service not known

The above exception was the direct cause of the following exception:

Traceback (most recent call last):
  File "/home/airflow/.local/lib/python3.12/site-packages/urllib3/connectionpool.py", line 793, in urlopen
    response = self._make_request(
               ^^^^^^^^^^^^^^^^^^^
  File "/home/airflow/.local/lib/python3.12/site-packages/urllib3/connectionpool.py", line 496, in _make_request
    conn.request(
  File "/home/airflow/.local/lib/python3.12/site-packages/urllib3/connection.py", line 400, in request
    self.endheaders()
  File "/usr/local/lib/python3.12/http/client.py", line 1331, in endheaders
    self._send_output(message_body, encode_chunked=encode_chunked)
  File "/usr/local/lib/python3.12/http/client.py", line 1091, in _send_output
    self.send(msg)
  File "/usr/local/lib/python3.12/http/client.py", line 1035, in send
    self.connect()
  File "/home/airflow/.local/lib/python3.12/site-packages/urllib3/connection.py", line 238, in connect
    self.sock = self._new_conn()
                ^^^^^^^^^^^^^^^^
  File "/home/airflow/.local/lib/python3.12/site-packages/urllib3/connection.py", line 205, in _new_conn
    raise NameResolutionError(self.host, self, e) from e
urllib3.exceptions.NameResolutionError: <urllib3.connection.HTTPConnection object at 0x7fc610c98290>: Failed to resolve 'flask' ([Errno -2] Name or service not known)

The above exception was the direct cause of the following exception:

Traceback (most recent call last):
  File "/home/airflow/.local/lib/python3.12/site-packages/requests/adapters.py", line 486, in send
    resp = conn.urlopen(
           ^^^^^^^^^^^^^
  File "/home/airflow/.local/lib/python3.12/site-packages/urllib3/connectionpool.py", line 847, in urlopen
    retries = retries.increment(
              ^^^^^^^^^^^^^^^^^^
  File "/home/airflow/.local/lib/python3.12/site-packages/urllib3/util/retry.py", line 515, in increment
    raise MaxRetryError(_pool, url, reason) from reason  # type: ignore[arg-type]
    ^^^^^^^^^^^^^^^^^^^^^^^^^^^^^^^^^^^^^^^^^^^^^^^^^^^
urllib3.exceptions.MaxRetryError: HTTPConnectionPool(host='flask', port=5000): Max retries exceeded with url: /check_send_status (Caused by NameResolutionError("<urllib3.connection.HTTPConnection object at 0x7fc610c98290>: Failed to resolve 'flask' ([Errno -2] Name or service not known)"))

During handling of the above exception, another exception occurred:

Traceback (most recent call last):
  File "/home/airflow/.local/lib/python3.12/site-packages/airflow/models/taskinstance.py", line 465, in _execute_task
    result = _execute_callable(context=context, **execute_callable_kwargs)
             ^^^^^^^^^^^^^^^^^^^^^^^^^^^^^^^^^^^^^^^^^^^^^^^^^^^^^^^^^^^^^
  File "/home/airflow/.local/lib/python3.12/site-packages/airflow/models/taskinstance.py", line 432, in _execute_callable
    return execute_callable(context=context, **execute_callable_kwargs)
           ^^^^^^^^^^^^^^^^^^^^^^^^^^^^^^^^^^^^^^^^^^^^^^^^^^^^^^^^^^^^
  File "/home/airflow/.local/lib/python3.12/site-packages/airflow/models/baseoperator.py", line 400, in wrapper
    return func(self, *args, **kwargs)
           ^^^^^^^^^^^^^^^^^^^^^^^^^^^
  File "/home/airflow/.local/lib/python3.12/site-packages/airflow/operators/python.py", line 235, in execute
    return_value = self.execute_callable()
                   ^^^^^^^^^^^^^^^^^^^^^^^
  File "/home/airflow/.local/lib/python3.12/site-packages/airflow/operators/python.py", line 252, in execute_callable
    return self.python_callable(*self.op_args, **self.op_kwargs)
           ^^^^^^^^^^^^^^^^^^^^^^^^^^^^^^^^^^^^^^^^^^^^^^^^^^^^^
  File "/opt/airflow/dags/check_send_status_dag.py", line 10, in check_send_status
    response = requests.get("http://flask:5000/check_send_status")
               ^^^^^^^^^^^^^^^^^^^^^^^^^^^^^^^^^^^^^^^^^^^^^^^^^^^
  File "/home/airflow/.local/lib/python3.12/site-packages/requests/api.py", line 73, in get
    return request("get", url, params=params, **kwargs)
           ^^^^^^^^^^^^^^^^^^^^^^^^^^^^^^^^^^^^^^^^^^^^
  File "/home/airflow/.local/lib/python3.12/site-packages/requests/api.py", line 59, in request
    return session.request(method=method, url=url, **kwargs)
           ^^^^^^^^^^^^^^^^^^^^^^^^^^^^^^^^^^^^^^^^^^^^^^^^^
  File "/home/airflow/.local/lib/python3.12/site-packages/requests/sessions.py", line 589, in request
    resp = self.send(prep, **send_kwargs)
           ^^^^^^^^^^^^^^^^^^^^^^^^^^^^^^
  File "/home/airflow/.local/lib/python3.12/site-packages/requests/sessions.py", line 703, in send
    r = adapter.send(request, **kwargs)
        ^^^^^^^^^^^^^^^^^^^^^^^^^^^^^^^
  File "/home/airflow/.local/lib/python3.12/site-packages/requests/adapters.py", line 519, in send
    raise ConnectionError(e, request=request)
requests.exceptions.ConnectionError: HTTPConnectionPool(host='flask', port=5000): Max retries exceeded with url: /check_send_status (Caused by NameResolutionError("<urllib3.connection.HTTPConnection object at 0x7fc610c98290>: Failed to resolve 'flask' ([Errno -2] Name or service not known)"))
[2024-05-29T15:11:37.711+0000] {taskinstance.py:1206} INFO - Marking task as FAILED. dag_id=check_send_status_dag, task_id=check_status, run_id=scheduled__2023-01-01T08:10:00+00:00, execution_date=20230101T081000, start_date=20240529T151133, end_date=20240529T151137
[2024-05-29T15:11:37.941+0000] {standard_task_runner.py:110} ERROR - Failed to execute job 96 for task check_status (HTTPConnectionPool(host='flask', port=5000): Max retries exceeded with url: /check_send_status (Caused by NameResolutionError("<urllib3.connection.HTTPConnection object at 0x7fc610c98290>: Failed to resolve 'flask' ([Errno -2] Name or service not known)")); 79)
[2024-05-29T15:11:37.962+0000] {local_task_job_runner.py:240} INFO - Task exited with return code 1
[2024-05-29T15:11:38.020+0000] {taskinstance.py:3498} INFO - 0 downstream tasks scheduled from follow-on schedule check
[2024-05-29T15:11:38.024+0000] {local_task_job_runner.py:222} INFO - ::endgroup::
