[2024-05-29T11:01:09.196+0000] {local_task_job_runner.py:120} INFO - ::group::Pre task execution logs
[2024-05-29T11:01:09.242+0000] {taskinstance.py:2076} INFO - Dependencies all met for dep_context=non-requeueable deps ti=<TaskInstance: check_send_status_dag.check_status scheduled__2023-01-01T08:00:00+00:00 [queued]>
[2024-05-29T11:01:09.261+0000] {taskinstance.py:2076} INFO - Dependencies all met for dep_context=requeueable deps ti=<TaskInstance: check_send_status_dag.check_status scheduled__2023-01-01T08:00:00+00:00 [queued]>
[2024-05-29T11:01:09.262+0000] {taskinstance.py:2306} INFO - Starting attempt 1 of 2
[2024-05-29T11:01:09.315+0000] {taskinstance.py:2330} INFO - Executing <Task(PythonOperator): check_status> on 2023-01-01 08:00:00+00:00
[2024-05-29T11:01:09.322+0000] {standard_task_runner.py:63} INFO - Started process 514 to run task
[2024-05-29T11:01:09.325+0000] {standard_task_runner.py:90} INFO - Running: ['airflow', 'tasks', 'run', 'check_send_status_dag', 'check_status', 'scheduled__2023-01-01T08:00:00+00:00', '--job-id', '90', '--raw', '--subdir', 'DAGS_FOLDER/check_send_status_dag.py', '--cfg-path', '/tmp/tmp5vwo_tzg']
[2024-05-29T11:01:09.327+0000] {standard_task_runner.py:91} INFO - Job 90: Subtask check_status
[2024-05-29T11:01:09.442+0000] {task_command.py:426} INFO - Running <TaskInstance: check_send_status_dag.check_status scheduled__2023-01-01T08:00:00+00:00 [running]> on host f708138922bb
[2024-05-29T11:01:09.697+0000] {taskinstance.py:2648} INFO - Exporting env vars: AIRFLOW_CTX_DAG_OWNER='airflow' AIRFLOW_CTX_DAG_ID='check_send_status_dag' AIRFLOW_CTX_TASK_ID='check_status' AIRFLOW_CTX_EXECUTION_DATE='2023-01-01T08:00:00+00:00' AIRFLOW_CTX_TRY_NUMBER='1' AIRFLOW_CTX_DAG_RUN_ID='scheduled__2023-01-01T08:00:00+00:00'
[2024-05-29T11:01:09.699+0000] {taskinstance.py:430} INFO - ::endgroup::
[2024-05-29T11:01:10.306+0000] {check_send_status_dag.py:15} ERROR - Error fetching status: 404 Client Error: Not Found for url: http://host.docker.internal/check_send_status
[2024-05-29T11:01:10.307+0000] {taskinstance.py:441} INFO - ::group::Post task execution logs
[2024-05-29T11:01:10.308+0000] {taskinstance.py:2905} ERROR - Task failed with exception
Traceback (most recent call last):
  File "/home/airflow/.local/lib/python3.12/site-packages/airflow/models/taskinstance.py", line 465, in _execute_task
    result = _execute_callable(context=context, **execute_callable_kwargs)
             ^^^^^^^^^^^^^^^^^^^^^^^^^^^^^^^^^^^^^^^^^^^^^^^^^^^^^^^^^^^^^
  File "/home/airflow/.local/lib/python3.12/site-packages/airflow/models/taskinstance.py", line 432, in _execute_callable
    return execute_callable(context=context, **execute_callable_kwargs)
           ^^^^^^^^^^^^^^^^^^^^^^^^^^^^^^^^^^^^^^^^^^^^^^^^^^^^^^^^^^^^
  File "/home/airflow/.local/lib/python3.12/site-packages/airflow/models/baseoperator.py", line 400, in wrapper
    return func(self, *args, **kwargs)
           ^^^^^^^^^^^^^^^^^^^^^^^^^^^
  File "/home/airflow/.local/lib/python3.12/site-packages/airflow/operators/python.py", line 235, in execute
    return_value = self.execute_callable()
                   ^^^^^^^^^^^^^^^^^^^^^^^
  File "/home/airflow/.local/lib/python3.12/site-packages/airflow/operators/python.py", line 252, in execute_callable
    return self.python_callable(*self.op_args, **self.op_kwargs)
           ^^^^^^^^^^^^^^^^^^^^^^^^^^^^^^^^^^^^^^^^^^^^^^^^^^^^^
  File "/opt/airflow/dags/check_send_status_dag.py", line 11, in check_send_status
    response.raise_for_status()
  File "/home/airflow/.local/lib/python3.12/site-packages/requests/models.py", line 1021, in raise_for_status
    raise HTTPError(http_error_msg, response=self)
requests.exceptions.HTTPError: 404 Client Error: Not Found for url: http://host.docker.internal/check_send_status
[2024-05-29T11:01:10.331+0000] {taskinstance.py:1206} INFO - Marking task as UP_FOR_RETRY. dag_id=check_send_status_dag, task_id=check_status, run_id=scheduled__2023-01-01T08:00:00+00:00, execution_date=20230101T080000, start_date=20240529T110109, end_date=20240529T110110
[2024-05-29T11:01:10.378+0000] {standard_task_runner.py:110} ERROR - Failed to execute job 90 for task check_status (404 Client Error: Not Found for url: http://host.docker.internal/check_send_status; 514)
[2024-05-29T11:01:10.423+0000] {local_task_job_runner.py:240} INFO - Task exited with return code 1
[2024-05-29T11:01:10.452+0000] {taskinstance.py:3498} INFO - 0 downstream tasks scheduled from follow-on schedule check
[2024-05-29T11:01:10.454+0000] {local_task_job_runner.py:222} INFO - ::endgroup::
[2024-05-29T15:04:18.826+0000] {local_task_job_runner.py:120} INFO - ::group::Pre task execution logs
[2024-05-29T15:04:18.873+0000] {taskinstance.py:2076} INFO - Dependencies all met for dep_context=non-requeueable deps ti=<TaskInstance: check_send_status_dag.check_status scheduled__2023-01-01T08:00:00+00:00 [queued]>
[2024-05-29T15:04:18.892+0000] {taskinstance.py:2076} INFO - Dependencies all met for dep_context=requeueable deps ti=<TaskInstance: check_send_status_dag.check_status scheduled__2023-01-01T08:00:00+00:00 [queued]>
[2024-05-29T15:04:18.893+0000] {taskinstance.py:2306} INFO - Starting attempt 1 of 2
[2024-05-29T15:04:18.950+0000] {taskinstance.py:2330} INFO - Executing <Task(PythonOperator): check_status> on 2023-01-01 08:00:00+00:00
[2024-05-29T15:04:18.956+0000] {standard_task_runner.py:63} INFO - Started process 121 to run task
[2024-05-29T15:04:18.959+0000] {standard_task_runner.py:90} INFO - Running: ['airflow', 'tasks', 'run', 'check_send_status_dag', 'check_status', 'scheduled__2023-01-01T08:00:00+00:00', '--job-id', '71', '--raw', '--subdir', 'DAGS_FOLDER/check_send_status_dag.py', '--cfg-path', '/tmp/tmp24ro1kve']
[2024-05-29T15:04:18.962+0000] {standard_task_runner.py:91} INFO - Job 71: Subtask check_status
[2024-05-29T15:04:19.085+0000] {task_command.py:426} INFO - Running <TaskInstance: check_send_status_dag.check_status scheduled__2023-01-01T08:00:00+00:00 [running]> on host f708138922bb
[2024-05-29T15:04:19.284+0000] {taskinstance.py:2648} INFO - Exporting env vars: AIRFLOW_CTX_DAG_OWNER='airflow' AIRFLOW_CTX_DAG_ID='check_send_status_dag' AIRFLOW_CTX_TASK_ID='check_status' AIRFLOW_CTX_EXECUTION_DATE='2023-01-01T08:00:00+00:00' AIRFLOW_CTX_TRY_NUMBER='1' AIRFLOW_CTX_DAG_RUN_ID='scheduled__2023-01-01T08:00:00+00:00'
[2024-05-29T15:04:19.286+0000] {taskinstance.py:430} INFO - ::endgroup::
[2024-05-29T15:04:19.318+0000] {check_send_status_dag.py:15} ERROR - Error fetching status: 500 Server Error: INTERNAL SERVER ERROR for url: http://flask:5000/check_send_status
[2024-05-29T15:04:19.321+0000] {taskinstance.py:441} INFO - ::group::Post task execution logs
[2024-05-29T15:04:19.324+0000] {taskinstance.py:2905} ERROR - Task failed with exception
Traceback (most recent call last):
  File "/home/airflow/.local/lib/python3.12/site-packages/airflow/models/taskinstance.py", line 465, in _execute_task
    result = _execute_callable(context=context, **execute_callable_kwargs)
             ^^^^^^^^^^^^^^^^^^^^^^^^^^^^^^^^^^^^^^^^^^^^^^^^^^^^^^^^^^^^^
  File "/home/airflow/.local/lib/python3.12/site-packages/airflow/models/taskinstance.py", line 432, in _execute_callable
    return execute_callable(context=context, **execute_callable_kwargs)
           ^^^^^^^^^^^^^^^^^^^^^^^^^^^^^^^^^^^^^^^^^^^^^^^^^^^^^^^^^^^^
  File "/home/airflow/.local/lib/python3.12/site-packages/airflow/models/baseoperator.py", line 400, in wrapper
    return func(self, *args, **kwargs)
           ^^^^^^^^^^^^^^^^^^^^^^^^^^^
  File "/home/airflow/.local/lib/python3.12/site-packages/airflow/operators/python.py", line 235, in execute
    return_value = self.execute_callable()
                   ^^^^^^^^^^^^^^^^^^^^^^^
  File "/home/airflow/.local/lib/python3.12/site-packages/airflow/operators/python.py", line 252, in execute_callable
    return self.python_callable(*self.op_args, **self.op_kwargs)
           ^^^^^^^^^^^^^^^^^^^^^^^^^^^^^^^^^^^^^^^^^^^^^^^^^^^^^
  File "/opt/airflow/dags/check_send_status_dag.py", line 11, in check_send_status
    response.raise_for_status()
  File "/home/airflow/.local/lib/python3.12/site-packages/requests/models.py", line 1021, in raise_for_status
    raise HTTPError(http_error_msg, response=self)
requests.exceptions.HTTPError: 500 Server Error: INTERNAL SERVER ERROR for url: http://flask:5000/check_send_status
[2024-05-29T15:04:19.379+0000] {taskinstance.py:1206} INFO - Marking task as UP_FOR_RETRY. dag_id=check_send_status_dag, task_id=check_status, run_id=scheduled__2023-01-01T08:00:00+00:00, execution_date=20230101T080000, start_date=20240529T150418, end_date=20240529T150419
[2024-05-29T15:04:19.435+0000] {standard_task_runner.py:110} ERROR - Failed to execute job 71 for task check_status (500 Server Error: INTERNAL SERVER ERROR for url: http://flask:5000/check_send_status; 121)
[2024-05-29T15:04:19.453+0000] {local_task_job_runner.py:240} INFO - Task exited with return code 1
[2024-05-29T15:04:19.481+0000] {taskinstance.py:3498} INFO - 0 downstream tasks scheduled from follow-on schedule check
[2024-05-29T15:04:19.482+0000] {local_task_job_runner.py:222} INFO - ::endgroup::
