[2024-05-29T13:06:44.667+0000] {local_task_job_runner.py:120} INFO - ::group::Pre task execution logs
[2024-05-29T13:06:44.806+0000] {taskinstance.py:2076} INFO - Dependencies all met for dep_context=non-requeueable deps ti=<TaskInstance: check_send_status_dag.check_status scheduled__2023-01-01T08:00:00+00:00 [queued]>
[2024-05-29T13:06:44.922+0000] {taskinstance.py:2076} INFO - Dependencies all met for dep_context=requeueable deps ti=<TaskInstance: check_send_status_dag.check_status scheduled__2023-01-01T08:00:00+00:00 [queued]>
[2024-05-29T13:06:44.923+0000] {taskinstance.py:2306} INFO - Starting attempt 2 of 2
[2024-05-29T13:06:45.053+0000] {taskinstance.py:2330} INFO - Executing <Task(PythonOperator): check_status> on 2023-01-01 08:00:00+00:00
[2024-05-29T13:06:45.060+0000] {standard_task_runner.py:63} INFO - Started process 601 to run task
[2024-05-29T13:06:45.064+0000] {standard_task_runner.py:90} INFO - Running: ['airflow', 'tasks', 'run', 'check_send_status_dag', 'check_status', 'scheduled__2023-01-01T08:00:00+00:00', '--job-id', '107', '--raw', '--subdir', 'DAGS_FOLDER/check_send_status_dag.py', '--cfg-path', '/tmp/tmp_c9s5r30']
[2024-05-29T13:06:45.066+0000] {standard_task_runner.py:91} INFO - Job 107: Subtask check_status
[2024-05-29T13:06:45.182+0000] {task_command.py:426} INFO - Running <TaskInstance: check_send_status_dag.check_status scheduled__2023-01-01T08:00:00+00:00 [running]> on host f708138922bb
[2024-05-29T13:06:45.350+0000] {taskinstance.py:2648} INFO - Exporting env vars: AIRFLOW_CTX_DAG_OWNER='airflow' AIRFLOW_CTX_DAG_ID='check_send_status_dag' AIRFLOW_CTX_TASK_ID='check_status' AIRFLOW_CTX_EXECUTION_DATE='2023-01-01T08:00:00+00:00' AIRFLOW_CTX_TRY_NUMBER='2' AIRFLOW_CTX_DAG_RUN_ID='scheduled__2023-01-01T08:00:00+00:00'
[2024-05-29T13:06:45.351+0000] {taskinstance.py:430} INFO - ::endgroup::
[2024-05-29T13:06:45.702+0000] {check_send_status_dag.py:15} ERROR - Error fetching status: 404 Client Error: Not Found for url: http://host.docker.internal/check_send_status
[2024-05-29T13:06:45.703+0000] {taskinstance.py:441} INFO - ::group::Post task execution logs
[2024-05-29T13:06:45.704+0000] {taskinstance.py:2905} ERROR - Task failed with exception
Traceback (most recent call last):
  File "/home/airflow/.local/lib/python3.12/site-packages/airflow/models/taskinstance.py", line 465, in _execute_task
    result = _execute_callable(context=context, **execute_callable_kwargs)
             ^^^^^^^^^^^^^^^^^^^^^^^^^^^^^^^^^^^^^^^^^^^^^^^^^^^^^^^^^^^^^
  File "/home/airflow/.local/lib/python3.12/site-packages/airflow/models/taskinstance.py", line 432, in _execute_callable
    return execute_callable(context=context, **execute_callable_kwargs)
           ^^^^^^^^^^^^^^^^^^^^^^^^^^^^^^^^^^^^^^^^^^^^^^^^^^^^^^^^^^^^
  File "/home/airflow/.local/lib/python3.12/site-packages/airflow/models/baseoperator.py", line 400, in wrapper
    return func(self, *args, **kwargs)
           ^^^^^^^^^^^^^^^^^^^^^^^^^^^
  File "/home/airflow/.local/lib/python3.12/site-packages/airflow/operators/python.py", line 235, in execute
    return_value = self.execute_callable()
                   ^^^^^^^^^^^^^^^^^^^^^^^
  File "/home/airflow/.local/lib/python3.12/site-packages/airflow/operators/python.py", line 252, in execute_callable
    return self.python_callable(*self.op_args, **self.op_kwargs)
           ^^^^^^^^^^^^^^^^^^^^^^^^^^^^^^^^^^^^^^^^^^^^^^^^^^^^^
  File "/opt/airflow/dags/check_send_status_dag.py", line 11, in check_send_status
    response.raise_for_status()
  File "/home/airflow/.local/lib/python3.12/site-packages/requests/models.py", line 1021, in raise_for_status
    raise HTTPError(http_error_msg, response=self)
requests.exceptions.HTTPError: 404 Client Error: Not Found for url: http://host.docker.internal/check_send_status
[2024-05-29T13:06:45.728+0000] {taskinstance.py:1206} INFO - Marking task as FAILED. dag_id=check_send_status_dag, task_id=check_status, run_id=scheduled__2023-01-01T08:00:00+00:00, execution_date=20230101T080000, start_date=20240529T130644, end_date=20240529T130645
[2024-05-29T13:06:45.771+0000] {standard_task_runner.py:110} ERROR - Failed to execute job 107 for task check_status (404 Client Error: Not Found for url: http://host.docker.internal/check_send_status; 601)
[2024-05-29T13:06:45.799+0000] {local_task_job_runner.py:240} INFO - Task exited with return code 1
[2024-05-29T13:06:45.822+0000] {taskinstance.py:3498} INFO - 0 downstream tasks scheduled from follow-on schedule check
[2024-05-29T13:06:45.825+0000] {local_task_job_runner.py:222} INFO - ::endgroup::
[2024-05-29T15:11:23.569+0000] {local_task_job_runner.py:120} INFO - ::group::Pre task execution logs
[2024-05-29T15:11:23.637+0000] {taskinstance.py:2076} INFO - Dependencies all met for dep_context=non-requeueable deps ti=<TaskInstance: check_send_status_dag.check_status scheduled__2023-01-01T08:00:00+00:00 [queued]>
[2024-05-29T15:11:23.655+0000] {taskinstance.py:2076} INFO - Dependencies all met for dep_context=requeueable deps ti=<TaskInstance: check_send_status_dag.check_status scheduled__2023-01-01T08:00:00+00:00 [queued]>
[2024-05-29T15:11:23.656+0000] {taskinstance.py:2306} INFO - Starting attempt 2 of 2
[2024-05-29T15:11:23.705+0000] {taskinstance.py:2330} INFO - Executing <Task(PythonOperator): check_status> on 2023-01-01 08:00:00+00:00
[2024-05-29T15:11:23.711+0000] {standard_task_runner.py:63} INFO - Started process 74 to run task
[2024-05-29T15:11:23.715+0000] {standard_task_runner.py:90} INFO - Running: ['airflow', 'tasks', 'run', 'check_send_status_dag', 'check_status', 'scheduled__2023-01-01T08:00:00+00:00', '--job-id', '95', '--raw', '--subdir', 'DAGS_FOLDER/check_send_status_dag.py', '--cfg-path', '/tmp/tmptjy5us2w']
[2024-05-29T15:11:23.717+0000] {standard_task_runner.py:91} INFO - Job 95: Subtask check_status
[2024-05-29T15:11:23.826+0000] {task_command.py:426} INFO - Running <TaskInstance: check_send_status_dag.check_status scheduled__2023-01-01T08:00:00+00:00 [running]> on host f708138922bb
[2024-05-29T15:11:24.023+0000] {taskinstance.py:2648} INFO - Exporting env vars: AIRFLOW_CTX_DAG_OWNER='airflow' AIRFLOW_CTX_DAG_ID='check_send_status_dag' AIRFLOW_CTX_TASK_ID='check_status' AIRFLOW_CTX_EXECUTION_DATE='2023-01-01T08:00:00+00:00' AIRFLOW_CTX_TRY_NUMBER='2' AIRFLOW_CTX_DAG_RUN_ID='scheduled__2023-01-01T08:00:00+00:00'
[2024-05-29T15:11:24.024+0000] {taskinstance.py:430} INFO - ::endgroup::
[2024-05-29T15:11:27.341+0000] {check_send_status_dag.py:15} ERROR - Error fetching status: HTTPConnectionPool(host='flask', port=5000): Max retries exceeded with url: /check_send_status (Caused by NameResolutionError("<urllib3.connection.HTTPConnection object at 0x7fa0dea37bf0>: Failed to resolve 'flask' ([Errno -2] Name or service not known)"))
[2024-05-29T15:11:27.342+0000] {taskinstance.py:441} INFO - ::group::Post task execution logs
[2024-05-29T15:11:27.343+0000] {taskinstance.py:2905} ERROR - Task failed with exception
Traceback (most recent call last):
  File "/home/airflow/.local/lib/python3.12/site-packages/urllib3/connection.py", line 198, in _new_conn
    sock = connection.create_connection(
           ^^^^^^^^^^^^^^^^^^^^^^^^^^^^^
  File "/home/airflow/.local/lib/python3.12/site-packages/urllib3/util/connection.py", line 60, in create_connection
    for res in socket.getaddrinfo(host, port, family, socket.SOCK_STREAM):
               ^^^^^^^^^^^^^^^^^^^^^^^^^^^^^^^^^^^^^^^^^^^^^^^^^^^^^^^^^^
  File "/usr/local/lib/python3.12/socket.py", line 963, in getaddrinfo
    for res in _socket.getaddrinfo(host, port, family, type, proto, flags):
               ^^^^^^^^^^^^^^^^^^^^^^^^^^^^^^^^^^^^^^^^^^^^^^^^^^^^^^^^^^^
socket.gaierror: [Errno -2] Name or service not known

The above exception was the direct cause of the following exception:

Traceback (most recent call last):
  File "/home/airflow/.local/lib/python3.12/site-packages/urllib3/connectionpool.py", line 793, in urlopen
    response = self._make_request(
               ^^^^^^^^^^^^^^^^^^^
  File "/home/airflow/.local/lib/python3.12/site-packages/urllib3/connectionpool.py", line 496, in _make_request
    conn.request(
  File "/home/airflow/.local/lib/python3.12/site-packages/urllib3/connection.py", line 400, in request
    self.endheaders()
  File "/usr/local/lib/python3.12/http/client.py", line 1331, in endheaders
    self._send_output(message_body, encode_chunked=encode_chunked)
  File "/usr/local/lib/python3.12/http/client.py", line 1091, in _send_output
    self.send(msg)
  File "/usr/local/lib/python3.12/http/client.py", line 1035, in send
    self.connect()
  File "/home/airflow/.local/lib/python3.12/site-packages/urllib3/connection.py", line 238, in connect
    self.sock = self._new_conn()
                ^^^^^^^^^^^^^^^^
  File "/home/airflow/.local/lib/python3.12/site-packages/urllib3/connection.py", line 205, in _new_conn
    raise NameResolutionError(self.host, self, e) from e
urllib3.exceptions.NameResolutionError: <urllib3.connection.HTTPConnection object at 0x7fa0dea37bf0>: Failed to resolve 'flask' ([Errno -2] Name or service not known)

The above exception was the direct cause of the following exception:

Traceback (most recent call last):
  File "/home/airflow/.local/lib/python3.12/site-packages/requests/adapters.py", line 486, in send
    resp = conn.urlopen(
           ^^^^^^^^^^^^^
  File "/home/airflow/.local/lib/python3.12/site-packages/urllib3/connectionpool.py", line 847, in urlopen
    retries = retries.increment(
              ^^^^^^^^^^^^^^^^^^
  File "/home/airflow/.local/lib/python3.12/site-packages/urllib3/util/retry.py", line 515, in increment
    raise MaxRetryError(_pool, url, reason) from reason  # type: ignore[arg-type]
    ^^^^^^^^^^^^^^^^^^^^^^^^^^^^^^^^^^^^^^^^^^^^^^^^^^^
urllib3.exceptions.MaxRetryError: HTTPConnectionPool(host='flask', port=5000): Max retries exceeded with url: /check_send_status (Caused by NameResolutionError("<urllib3.connection.HTTPConnection object at 0x7fa0dea37bf0>: Failed to resolve 'flask' ([Errno -2] Name or service not known)"))

During handling of the above exception, another exception occurred:

Traceback (most recent call last):
  File "/home/airflow/.local/lib/python3.12/site-packages/airflow/models/taskinstance.py", line 465, in _execute_task
    result = _execute_callable(context=context, **execute_callable_kwargs)
             ^^^^^^^^^^^^^^^^^^^^^^^^^^^^^^^^^^^^^^^^^^^^^^^^^^^^^^^^^^^^^
  File "/home/airflow/.local/lib/python3.12/site-packages/airflow/models/taskinstance.py", line 432, in _execute_callable
    return execute_callable(context=context, **execute_callable_kwargs)
           ^^^^^^^^^^^^^^^^^^^^^^^^^^^^^^^^^^^^^^^^^^^^^^^^^^^^^^^^^^^^
  File "/home/airflow/.local/lib/python3.12/site-packages/airflow/models/baseoperator.py", line 400, in wrapper
    return func(self, *args, **kwargs)
           ^^^^^^^^^^^^^^^^^^^^^^^^^^^
  File "/home/airflow/.local/lib/python3.12/site-packages/airflow/operators/python.py", line 235, in execute
    return_value = self.execute_callable()
                   ^^^^^^^^^^^^^^^^^^^^^^^
  File "/home/airflow/.local/lib/python3.12/site-packages/airflow/operators/python.py", line 252, in execute_callable
    return self.python_callable(*self.op_args, **self.op_kwargs)
           ^^^^^^^^^^^^^^^^^^^^^^^^^^^^^^^^^^^^^^^^^^^^^^^^^^^^^
  File "/opt/airflow/dags/check_send_status_dag.py", line 10, in check_send_status
    response = requests.get("http://flask:5000/check_send_status")
               ^^^^^^^^^^^^^^^^^^^^^^^^^^^^^^^^^^^^^^^^^^^^^^^^^^^
  File "/home/airflow/.local/lib/python3.12/site-packages/requests/api.py", line 73, in get
    return request("get", url, params=params, **kwargs)
           ^^^^^^^^^^^^^^^^^^^^^^^^^^^^^^^^^^^^^^^^^^^^
  File "/home/airflow/.local/lib/python3.12/site-packages/requests/api.py", line 59, in request
    return session.request(method=method, url=url, **kwargs)
           ^^^^^^^^^^^^^^^^^^^^^^^^^^^^^^^^^^^^^^^^^^^^^^^^^
  File "/home/airflow/.local/lib/python3.12/site-packages/requests/sessions.py", line 589, in request
    resp = self.send(prep, **send_kwargs)
           ^^^^^^^^^^^^^^^^^^^^^^^^^^^^^^
  File "/home/airflow/.local/lib/python3.12/site-packages/requests/sessions.py", line 703, in send
    r = adapter.send(request, **kwargs)
        ^^^^^^^^^^^^^^^^^^^^^^^^^^^^^^^
  File "/home/airflow/.local/lib/python3.12/site-packages/requests/adapters.py", line 519, in send
    raise ConnectionError(e, request=request)
requests.exceptions.ConnectionError: HTTPConnectionPool(host='flask', port=5000): Max retries exceeded with url: /check_send_status (Caused by NameResolutionError("<urllib3.connection.HTTPConnection object at 0x7fa0dea37bf0>: Failed to resolve 'flask' ([Errno -2] Name or service not known)"))
[2024-05-29T15:11:27.374+0000] {taskinstance.py:1206} INFO - Marking task as FAILED. dag_id=check_send_status_dag, task_id=check_status, run_id=scheduled__2023-01-01T08:00:00+00:00, execution_date=20230101T080000, start_date=20240529T151123, end_date=20240529T151127
[2024-05-29T15:11:27.435+0000] {standard_task_runner.py:110} ERROR - Failed to execute job 95 for task check_status (HTTPConnectionPool(host='flask', port=5000): Max retries exceeded with url: /check_send_status (Caused by NameResolutionError("<urllib3.connection.HTTPConnection object at 0x7fa0dea37bf0>: Failed to resolve 'flask' ([Errno -2] Name or service not known)")); 74)
[2024-05-29T15:11:27.468+0000] {local_task_job_runner.py:240} INFO - Task exited with return code 1
[2024-05-29T15:11:27.502+0000] {taskinstance.py:3498} INFO - 0 downstream tasks scheduled from follow-on schedule check
[2024-05-29T15:11:27.505+0000] {local_task_job_runner.py:222} INFO - ::endgroup::
