[2024-05-29T10:59:36.249+0000] {local_task_job_runner.py:120} INFO - ::group::Pre task execution logs
[2024-05-29T10:59:36.297+0000] {taskinstance.py:2076} INFO - Dependencies all met for dep_context=non-requeueable deps ti=<TaskInstance: check_send_status_dag.check_status scheduled__2023-01-01T06:30:00+00:00 [queued]>
[2024-05-29T10:59:36.318+0000] {taskinstance.py:2076} INFO - Dependencies all met for dep_context=requeueable deps ti=<TaskInstance: check_send_status_dag.check_status scheduled__2023-01-01T06:30:00+00:00 [queued]>
[2024-05-29T10:59:36.320+0000] {taskinstance.py:2306} INFO - Starting attempt 1 of 2
[2024-05-29T10:59:36.374+0000] {taskinstance.py:2330} INFO - Executing <Task(PythonOperator): check_status> on 2023-01-01 06:30:00+00:00
[2024-05-29T10:59:36.380+0000] {standard_task_runner.py:63} INFO - Started process 456 to run task
[2024-05-29T10:59:36.383+0000] {standard_task_runner.py:90} INFO - Running: ['airflow', 'tasks', 'run', 'check_send_status_dag', 'check_status', 'scheduled__2023-01-01T06:30:00+00:00', '--job-id', '79', '--raw', '--subdir', 'DAGS_FOLDER/check_send_status_dag.py', '--cfg-path', '/tmp/tmpog3e7ixx']
[2024-05-29T10:59:36.385+0000] {standard_task_runner.py:91} INFO - Job 79: Subtask check_status
[2024-05-29T10:59:36.505+0000] {task_command.py:426} INFO - Running <TaskInstance: check_send_status_dag.check_status scheduled__2023-01-01T06:30:00+00:00 [running]> on host f708138922bb
[2024-05-29T10:59:36.718+0000] {taskinstance.py:2648} INFO - Exporting env vars: AIRFLOW_CTX_DAG_OWNER='airflow' AIRFLOW_CTX_DAG_ID='check_send_status_dag' AIRFLOW_CTX_TASK_ID='check_status' AIRFLOW_CTX_EXECUTION_DATE='2023-01-01T06:30:00+00:00' AIRFLOW_CTX_TRY_NUMBER='1' AIRFLOW_CTX_DAG_RUN_ID='scheduled__2023-01-01T06:30:00+00:00'
[2024-05-29T10:59:36.719+0000] {taskinstance.py:430} INFO - ::endgroup::
[2024-05-29T10:59:37.125+0000] {check_send_status_dag.py:15} ERROR - Error fetching status: 404 Client Error: Not Found for url: http://host.docker.internal/check_send_status
[2024-05-29T10:59:37.126+0000] {taskinstance.py:441} INFO - ::group::Post task execution logs
[2024-05-29T10:59:37.128+0000] {taskinstance.py:2905} ERROR - Task failed with exception
Traceback (most recent call last):
  File "/home/airflow/.local/lib/python3.12/site-packages/airflow/models/taskinstance.py", line 465, in _execute_task
    result = _execute_callable(context=context, **execute_callable_kwargs)
             ^^^^^^^^^^^^^^^^^^^^^^^^^^^^^^^^^^^^^^^^^^^^^^^^^^^^^^^^^^^^^
  File "/home/airflow/.local/lib/python3.12/site-packages/airflow/models/taskinstance.py", line 432, in _execute_callable
    return execute_callable(context=context, **execute_callable_kwargs)
           ^^^^^^^^^^^^^^^^^^^^^^^^^^^^^^^^^^^^^^^^^^^^^^^^^^^^^^^^^^^^
  File "/home/airflow/.local/lib/python3.12/site-packages/airflow/models/baseoperator.py", line 400, in wrapper
    return func(self, *args, **kwargs)
           ^^^^^^^^^^^^^^^^^^^^^^^^^^^
  File "/home/airflow/.local/lib/python3.12/site-packages/airflow/operators/python.py", line 235, in execute
    return_value = self.execute_callable()
                   ^^^^^^^^^^^^^^^^^^^^^^^
  File "/home/airflow/.local/lib/python3.12/site-packages/airflow/operators/python.py", line 252, in execute_callable
    return self.python_callable(*self.op_args, **self.op_kwargs)
           ^^^^^^^^^^^^^^^^^^^^^^^^^^^^^^^^^^^^^^^^^^^^^^^^^^^^^
  File "/opt/airflow/dags/check_send_status_dag.py", line 11, in check_send_status
    response.raise_for_status()
  File "/home/airflow/.local/lib/python3.12/site-packages/requests/models.py", line 1021, in raise_for_status
    raise HTTPError(http_error_msg, response=self)
requests.exceptions.HTTPError: 404 Client Error: Not Found for url: http://host.docker.internal/check_send_status
[2024-05-29T10:59:37.153+0000] {taskinstance.py:1206} INFO - Marking task as UP_FOR_RETRY. dag_id=check_send_status_dag, task_id=check_status, run_id=scheduled__2023-01-01T06:30:00+00:00, execution_date=20230101T063000, start_date=20240529T105936, end_date=20240529T105937
[2024-05-29T10:59:37.204+0000] {standard_task_runner.py:110} ERROR - Failed to execute job 79 for task check_status (404 Client Error: Not Found for url: http://host.docker.internal/check_send_status; 456)
[2024-05-29T10:59:37.239+0000] {local_task_job_runner.py:240} INFO - Task exited with return code 1
[2024-05-29T10:59:37.306+0000] {taskinstance.py:3498} INFO - 0 downstream tasks scheduled from follow-on schedule check
[2024-05-29T10:59:37.315+0000] {local_task_job_runner.py:222} INFO - ::endgroup::
[2024-05-29T14:32:57.461+0000] {local_task_job_runner.py:120} INFO - ::group::Pre task execution logs
[2024-05-29T14:32:57.561+0000] {taskinstance.py:2076} INFO - Dependencies all met for dep_context=non-requeueable deps ti=<TaskInstance: check_send_status_dag.check_status scheduled__2023-01-01T06:30:00+00:00 [queued]>
[2024-05-29T14:32:57.598+0000] {taskinstance.py:2076} INFO - Dependencies all met for dep_context=requeueable deps ti=<TaskInstance: check_send_status_dag.check_status scheduled__2023-01-01T06:30:00+00:00 [queued]>
[2024-05-29T14:32:57.599+0000] {taskinstance.py:2306} INFO - Starting attempt 1 of 2
[2024-05-29T14:32:57.666+0000] {taskinstance.py:2330} INFO - Executing <Task(PythonOperator): check_status> on 2023-01-01 06:30:00+00:00
[2024-05-29T14:32:57.672+0000] {standard_task_runner.py:63} INFO - Started process 1538 to run task
[2024-05-29T14:32:57.677+0000] {standard_task_runner.py:90} INFO - Running: ['airflow', 'tasks', 'run', 'check_send_status_dag', 'check_status', 'scheduled__2023-01-01T06:30:00+00:00', '--job-id', '68', '--raw', '--subdir', 'DAGS_FOLDER/check_send_status_dag.py', '--cfg-path', '/tmp/tmpbctns780']
[2024-05-29T14:32:57.680+0000] {standard_task_runner.py:91} INFO - Job 68: Subtask check_status
[2024-05-29T14:32:57.832+0000] {task_command.py:426} INFO - Running <TaskInstance: check_send_status_dag.check_status scheduled__2023-01-01T06:30:00+00:00 [running]> on host f708138922bb
[2024-05-29T14:32:58.119+0000] {taskinstance.py:2648} INFO - Exporting env vars: AIRFLOW_CTX_DAG_OWNER='airflow' AIRFLOW_CTX_DAG_ID='check_send_status_dag' AIRFLOW_CTX_TASK_ID='check_status' AIRFLOW_CTX_EXECUTION_DATE='2023-01-01T06:30:00+00:00' AIRFLOW_CTX_TRY_NUMBER='1' AIRFLOW_CTX_DAG_RUN_ID='scheduled__2023-01-01T06:30:00+00:00'
[2024-05-29T14:32:58.122+0000] {taskinstance.py:430} INFO - ::endgroup::
[2024-05-29T14:32:58.183+0000] {check_send_status_dag.py:15} ERROR - Error fetching status: 500 Server Error: INTERNAL SERVER ERROR for url: http://flask:5000/check_send_status
[2024-05-29T14:32:58.184+0000] {taskinstance.py:441} INFO - ::group::Post task execution logs
[2024-05-29T14:32:58.185+0000] {taskinstance.py:2905} ERROR - Task failed with exception
Traceback (most recent call last):
  File "/home/airflow/.local/lib/python3.12/site-packages/airflow/models/taskinstance.py", line 465, in _execute_task
    result = _execute_callable(context=context, **execute_callable_kwargs)
             ^^^^^^^^^^^^^^^^^^^^^^^^^^^^^^^^^^^^^^^^^^^^^^^^^^^^^^^^^^^^^
  File "/home/airflow/.local/lib/python3.12/site-packages/airflow/models/taskinstance.py", line 432, in _execute_callable
    return execute_callable(context=context, **execute_callable_kwargs)
           ^^^^^^^^^^^^^^^^^^^^^^^^^^^^^^^^^^^^^^^^^^^^^^^^^^^^^^^^^^^^
  File "/home/airflow/.local/lib/python3.12/site-packages/airflow/models/baseoperator.py", line 400, in wrapper
    return func(self, *args, **kwargs)
           ^^^^^^^^^^^^^^^^^^^^^^^^^^^
  File "/home/airflow/.local/lib/python3.12/site-packages/airflow/operators/python.py", line 235, in execute
    return_value = self.execute_callable()
                   ^^^^^^^^^^^^^^^^^^^^^^^
  File "/home/airflow/.local/lib/python3.12/site-packages/airflow/operators/python.py", line 252, in execute_callable
    return self.python_callable(*self.op_args, **self.op_kwargs)
           ^^^^^^^^^^^^^^^^^^^^^^^^^^^^^^^^^^^^^^^^^^^^^^^^^^^^^
  File "/opt/airflow/dags/check_send_status_dag.py", line 11, in check_send_status
    response.raise_for_status()
  File "/home/airflow/.local/lib/python3.12/site-packages/requests/models.py", line 1021, in raise_for_status
    raise HTTPError(http_error_msg, response=self)
requests.exceptions.HTTPError: 500 Server Error: INTERNAL SERVER ERROR for url: http://flask:5000/check_send_status
[2024-05-29T14:32:58.217+0000] {taskinstance.py:1206} INFO - Marking task as UP_FOR_RETRY. dag_id=check_send_status_dag, task_id=check_status, run_id=scheduled__2023-01-01T06:30:00+00:00, execution_date=20230101T063000, start_date=20240529T143257, end_date=20240529T143258
[2024-05-29T14:32:58.278+0000] {standard_task_runner.py:110} ERROR - Failed to execute job 68 for task check_status (500 Server Error: INTERNAL SERVER ERROR for url: http://flask:5000/check_send_status; 1538)
[2024-05-29T14:32:58.306+0000] {local_task_job_runner.py:240} INFO - Task exited with return code 1
[2024-05-29T14:32:58.372+0000] {taskinstance.py:3498} INFO - 0 downstream tasks scheduled from follow-on schedule check
[2024-05-29T14:32:58.377+0000] {local_task_job_runner.py:222} INFO - ::endgroup::
[2024-05-29T15:02:44.101+0000] {local_task_job_runner.py:120} INFO - ::group::Pre task execution logs
[2024-05-29T15:02:44.149+0000] {taskinstance.py:2076} INFO - Dependencies all met for dep_context=non-requeueable deps ti=<TaskInstance: check_send_status_dag.check_status scheduled__2023-01-01T06:30:00+00:00 [queued]>
[2024-05-29T15:02:44.172+0000] {taskinstance.py:2076} INFO - Dependencies all met for dep_context=requeueable deps ti=<TaskInstance: check_send_status_dag.check_status scheduled__2023-01-01T06:30:00+00:00 [queued]>
[2024-05-29T15:02:44.173+0000] {taskinstance.py:2306} INFO - Starting attempt 1 of 2
[2024-05-29T15:02:44.230+0000] {taskinstance.py:2330} INFO - Executing <Task(PythonOperator): check_status> on 2023-01-01 06:30:00+00:00
[2024-05-29T15:02:44.237+0000] {standard_task_runner.py:63} INFO - Started process 68 to run task
[2024-05-29T15:02:44.241+0000] {standard_task_runner.py:90} INFO - Running: ['airflow', 'tasks', 'run', 'check_send_status_dag', 'check_status', 'scheduled__2023-01-01T06:30:00+00:00', '--job-id', '61', '--raw', '--subdir', 'DAGS_FOLDER/check_send_status_dag.py', '--cfg-path', '/tmp/tmpyut6ggx5']
[2024-05-29T15:02:44.245+0000] {standard_task_runner.py:91} INFO - Job 61: Subtask check_status
[2024-05-29T15:02:44.386+0000] {task_command.py:426} INFO - Running <TaskInstance: check_send_status_dag.check_status scheduled__2023-01-01T06:30:00+00:00 [running]> on host f708138922bb
[2024-05-29T15:02:44.952+0000] {taskinstance.py:2648} INFO - Exporting env vars: AIRFLOW_CTX_DAG_OWNER='airflow' AIRFLOW_CTX_DAG_ID='check_send_status_dag' AIRFLOW_CTX_TASK_ID='check_status' AIRFLOW_CTX_EXECUTION_DATE='2023-01-01T06:30:00+00:00' AIRFLOW_CTX_TRY_NUMBER='1' AIRFLOW_CTX_DAG_RUN_ID='scheduled__2023-01-01T06:30:00+00:00'
[2024-05-29T15:02:44.955+0000] {taskinstance.py:430} INFO - ::endgroup::
[2024-05-29T15:02:45.003+0000] {check_send_status_dag.py:15} ERROR - Error fetching status: 500 Server Error: INTERNAL SERVER ERROR for url: http://flask:5000/check_send_status
[2024-05-29T15:02:45.009+0000] {taskinstance.py:441} INFO - ::group::Post task execution logs
[2024-05-29T15:02:45.014+0000] {taskinstance.py:2905} ERROR - Task failed with exception
Traceback (most recent call last):
  File "/home/airflow/.local/lib/python3.12/site-packages/airflow/models/taskinstance.py", line 465, in _execute_task
    result = _execute_callable(context=context, **execute_callable_kwargs)
             ^^^^^^^^^^^^^^^^^^^^^^^^^^^^^^^^^^^^^^^^^^^^^^^^^^^^^^^^^^^^^
  File "/home/airflow/.local/lib/python3.12/site-packages/airflow/models/taskinstance.py", line 432, in _execute_callable
    return execute_callable(context=context, **execute_callable_kwargs)
           ^^^^^^^^^^^^^^^^^^^^^^^^^^^^^^^^^^^^^^^^^^^^^^^^^^^^^^^^^^^^
  File "/home/airflow/.local/lib/python3.12/site-packages/airflow/models/baseoperator.py", line 400, in wrapper
    return func(self, *args, **kwargs)
           ^^^^^^^^^^^^^^^^^^^^^^^^^^^
  File "/home/airflow/.local/lib/python3.12/site-packages/airflow/operators/python.py", line 235, in execute
    return_value = self.execute_callable()
                   ^^^^^^^^^^^^^^^^^^^^^^^
  File "/home/airflow/.local/lib/python3.12/site-packages/airflow/operators/python.py", line 252, in execute_callable
    return self.python_callable(*self.op_args, **self.op_kwargs)
           ^^^^^^^^^^^^^^^^^^^^^^^^^^^^^^^^^^^^^^^^^^^^^^^^^^^^^
  File "/opt/airflow/dags/check_send_status_dag.py", line 11, in check_send_status
    response.raise_for_status()
  File "/home/airflow/.local/lib/python3.12/site-packages/requests/models.py", line 1021, in raise_for_status
    raise HTTPError(http_error_msg, response=self)
requests.exceptions.HTTPError: 500 Server Error: INTERNAL SERVER ERROR for url: http://flask:5000/check_send_status
[2024-05-29T15:02:45.121+0000] {taskinstance.py:1206} INFO - Marking task as UP_FOR_RETRY. dag_id=check_send_status_dag, task_id=check_status, run_id=scheduled__2023-01-01T06:30:00+00:00, execution_date=20230101T063000, start_date=20240529T150244, end_date=20240529T150245
[2024-05-29T15:02:45.178+0000] {standard_task_runner.py:110} ERROR - Failed to execute job 61 for task check_status (500 Server Error: INTERNAL SERVER ERROR for url: http://flask:5000/check_send_status; 68)
[2024-05-29T15:02:45.225+0000] {local_task_job_runner.py:240} INFO - Task exited with return code 1
[2024-05-29T15:02:45.259+0000] {taskinstance.py:3498} INFO - 0 downstream tasks scheduled from follow-on schedule check
[2024-05-29T15:02:45.263+0000] {local_task_job_runner.py:222} INFO - ::endgroup::
