[2024-05-29T10:42:56.844+0000] {local_task_job_runner.py:120} INFO - ::group::Pre task execution logs
[2024-05-29T10:42:56.889+0000] {taskinstance.py:2076} INFO - Dependencies all met for dep_context=non-requeueable deps ti=<TaskInstance: check_send_status_dag.check_status scheduled__2023-01-01T00:20:00+00:00 [queued]>
[2024-05-29T10:42:56.909+0000] {taskinstance.py:2076} INFO - Dependencies all met for dep_context=requeueable deps ti=<TaskInstance: check_send_status_dag.check_status scheduled__2023-01-01T00:20:00+00:00 [queued]>
[2024-05-29T10:42:56.910+0000] {taskinstance.py:2306} INFO - Starting attempt 1 of 2
[2024-05-29T10:42:56.970+0000] {taskinstance.py:2330} INFO - Executing <Task(PythonOperator): check_status> on 2023-01-01 00:20:00+00:00
[2024-05-29T10:42:56.977+0000] {standard_task_runner.py:63} INFO - Started process 82 to run task
[2024-05-29T10:42:56.980+0000] {standard_task_runner.py:90} INFO - Running: ['airflow', 'tasks', 'run', 'check_send_status_dag', 'check_status', 'scheduled__2023-01-01T00:20:00+00:00', '--job-id', '10', '--raw', '--subdir', 'DAGS_FOLDER/check_send_status_dag.py', '--cfg-path', '/tmp/tmp7t4rdl7w']
[2024-05-29T10:42:56.986+0000] {standard_task_runner.py:91} INFO - Job 10: Subtask check_status
[2024-05-29T10:42:57.104+0000] {task_command.py:426} INFO - Running <TaskInstance: check_send_status_dag.check_status scheduled__2023-01-01T00:20:00+00:00 [running]> on host f708138922bb
[2024-05-29T10:42:57.333+0000] {taskinstance.py:2648} INFO - Exporting env vars: AIRFLOW_CTX_DAG_OWNER='airflow' AIRFLOW_CTX_DAG_ID='check_send_status_dag' AIRFLOW_CTX_TASK_ID='check_status' AIRFLOW_CTX_EXECUTION_DATE='2023-01-01T00:20:00+00:00' AIRFLOW_CTX_TRY_NUMBER='1' AIRFLOW_CTX_DAG_RUN_ID='scheduled__2023-01-01T00:20:00+00:00'
[2024-05-29T10:42:57.335+0000] {taskinstance.py:430} INFO - ::endgroup::
[2024-05-29T10:42:57.357+0000] {check_send_status_dag.py:15} ERROR - Error fetching status: HTTPConnectionPool(host='127.0.0.1', port=5000): Max retries exceeded with url: /check_send_status (Caused by NewConnectionError('<urllib3.connection.HTTPConnection object at 0x7f78278125a0>: Failed to establish a new connection: [Errno 111] Connection refused'))
[2024-05-29T10:42:57.358+0000] {taskinstance.py:441} INFO - ::group::Post task execution logs
[2024-05-29T10:42:57.358+0000] {taskinstance.py:2905} ERROR - Task failed with exception
Traceback (most recent call last):
  File "/home/airflow/.local/lib/python3.12/site-packages/urllib3/connection.py", line 198, in _new_conn
    sock = connection.create_connection(
           ^^^^^^^^^^^^^^^^^^^^^^^^^^^^^
  File "/home/airflow/.local/lib/python3.12/site-packages/urllib3/util/connection.py", line 85, in create_connection
    raise err
  File "/home/airflow/.local/lib/python3.12/site-packages/urllib3/util/connection.py", line 73, in create_connection
    sock.connect(sa)
ConnectionRefusedError: [Errno 111] Connection refused

The above exception was the direct cause of the following exception:

Traceback (most recent call last):
  File "/home/airflow/.local/lib/python3.12/site-packages/urllib3/connectionpool.py", line 793, in urlopen
    response = self._make_request(
               ^^^^^^^^^^^^^^^^^^^
  File "/home/airflow/.local/lib/python3.12/site-packages/urllib3/connectionpool.py", line 496, in _make_request
    conn.request(
  File "/home/airflow/.local/lib/python3.12/site-packages/urllib3/connection.py", line 400, in request
    self.endheaders()
  File "/usr/local/lib/python3.12/http/client.py", line 1331, in endheaders
    self._send_output(message_body, encode_chunked=encode_chunked)
  File "/usr/local/lib/python3.12/http/client.py", line 1091, in _send_output
    self.send(msg)
  File "/usr/local/lib/python3.12/http/client.py", line 1035, in send
    self.connect()
  File "/home/airflow/.local/lib/python3.12/site-packages/urllib3/connection.py", line 238, in connect
    self.sock = self._new_conn()
                ^^^^^^^^^^^^^^^^
  File "/home/airflow/.local/lib/python3.12/site-packages/urllib3/connection.py", line 213, in _new_conn
    raise NewConnectionError(
urllib3.exceptions.NewConnectionError: <urllib3.connection.HTTPConnection object at 0x7f78278125a0>: Failed to establish a new connection: [Errno 111] Connection refused

The above exception was the direct cause of the following exception:

Traceback (most recent call last):
  File "/home/airflow/.local/lib/python3.12/site-packages/requests/adapters.py", line 486, in send
    resp = conn.urlopen(
           ^^^^^^^^^^^^^
  File "/home/airflow/.local/lib/python3.12/site-packages/urllib3/connectionpool.py", line 847, in urlopen
    retries = retries.increment(
              ^^^^^^^^^^^^^^^^^^
  File "/home/airflow/.local/lib/python3.12/site-packages/urllib3/util/retry.py", line 515, in increment
    raise MaxRetryError(_pool, url, reason) from reason  # type: ignore[arg-type]
    ^^^^^^^^^^^^^^^^^^^^^^^^^^^^^^^^^^^^^^^^^^^^^^^^^^^
urllib3.exceptions.MaxRetryError: HTTPConnectionPool(host='127.0.0.1', port=5000): Max retries exceeded with url: /check_send_status (Caused by NewConnectionError('<urllib3.connection.HTTPConnection object at 0x7f78278125a0>: Failed to establish a new connection: [Errno 111] Connection refused'))

During handling of the above exception, another exception occurred:

Traceback (most recent call last):
  File "/home/airflow/.local/lib/python3.12/site-packages/airflow/models/taskinstance.py", line 465, in _execute_task
    result = _execute_callable(context=context, **execute_callable_kwargs)
             ^^^^^^^^^^^^^^^^^^^^^^^^^^^^^^^^^^^^^^^^^^^^^^^^^^^^^^^^^^^^^
  File "/home/airflow/.local/lib/python3.12/site-packages/airflow/models/taskinstance.py", line 432, in _execute_callable
    return execute_callable(context=context, **execute_callable_kwargs)
           ^^^^^^^^^^^^^^^^^^^^^^^^^^^^^^^^^^^^^^^^^^^^^^^^^^^^^^^^^^^^
  File "/home/airflow/.local/lib/python3.12/site-packages/airflow/models/baseoperator.py", line 400, in wrapper
    return func(self, *args, **kwargs)
           ^^^^^^^^^^^^^^^^^^^^^^^^^^^
  File "/home/airflow/.local/lib/python3.12/site-packages/airflow/operators/python.py", line 235, in execute
    return_value = self.execute_callable()
                   ^^^^^^^^^^^^^^^^^^^^^^^
  File "/home/airflow/.local/lib/python3.12/site-packages/airflow/operators/python.py", line 252, in execute_callable
    return self.python_callable(*self.op_args, **self.op_kwargs)
           ^^^^^^^^^^^^^^^^^^^^^^^^^^^^^^^^^^^^^^^^^^^^^^^^^^^^^
  File "/opt/airflow/dags/check_send_status_dag.py", line 10, in check_send_status
    response = requests.get("http://127.0.0.1:5000/check_send_status")
               ^^^^^^^^^^^^^^^^^^^^^^^^^^^^^^^^^^^^^^^^^^^^^^^^^^^^^^^
  File "/home/airflow/.local/lib/python3.12/site-packages/requests/api.py", line 73, in get
    return request("get", url, params=params, **kwargs)
           ^^^^^^^^^^^^^^^^^^^^^^^^^^^^^^^^^^^^^^^^^^^^
  File "/home/airflow/.local/lib/python3.12/site-packages/requests/api.py", line 59, in request
    return session.request(method=method, url=url, **kwargs)
           ^^^^^^^^^^^^^^^^^^^^^^^^^^^^^^^^^^^^^^^^^^^^^^^^^
  File "/home/airflow/.local/lib/python3.12/site-packages/requests/sessions.py", line 589, in request
    resp = self.send(prep, **send_kwargs)
           ^^^^^^^^^^^^^^^^^^^^^^^^^^^^^^
  File "/home/airflow/.local/lib/python3.12/site-packages/requests/sessions.py", line 703, in send
    r = adapter.send(request, **kwargs)
        ^^^^^^^^^^^^^^^^^^^^^^^^^^^^^^^
  File "/home/airflow/.local/lib/python3.12/site-packages/requests/adapters.py", line 519, in send
    raise ConnectionError(e, request=request)
requests.exceptions.ConnectionError: HTTPConnectionPool(host='127.0.0.1', port=5000): Max retries exceeded with url: /check_send_status (Caused by NewConnectionError('<urllib3.connection.HTTPConnection object at 0x7f78278125a0>: Failed to establish a new connection: [Errno 111] Connection refused'))
[2024-05-29T10:42:57.384+0000] {taskinstance.py:1206} INFO - Marking task as UP_FOR_RETRY. dag_id=check_send_status_dag, task_id=check_status, run_id=scheduled__2023-01-01T00:20:00+00:00, execution_date=20230101T002000, start_date=20240529T104256, end_date=20240529T104257
[2024-05-29T10:42:57.423+0000] {standard_task_runner.py:110} ERROR - Failed to execute job 10 for task check_status (HTTPConnectionPool(host='127.0.0.1', port=5000): Max retries exceeded with url: /check_send_status (Caused by NewConnectionError('<urllib3.connection.HTTPConnection object at 0x7f78278125a0>: Failed to establish a new connection: [Errno 111] Connection refused')); 82)
[2024-05-29T10:42:57.444+0000] {local_task_job_runner.py:240} INFO - Task exited with return code 1
[2024-05-29T10:42:57.475+0000] {taskinstance.py:3498} INFO - 0 downstream tasks scheduled from follow-on schedule check
[2024-05-29T10:42:57.486+0000] {local_task_job_runner.py:222} INFO - ::endgroup::
[2024-05-29T13:54:05.444+0000] {local_task_job_runner.py:120} INFO - ::group::Pre task execution logs
[2024-05-29T13:54:05.701+0000] {taskinstance.py:2076} INFO - Dependencies all met for dep_context=non-requeueable deps ti=<TaskInstance: check_send_status_dag.check_status scheduled__2023-01-01T00:20:00+00:00 [queued]>
[2024-05-29T13:54:05.759+0000] {taskinstance.py:2076} INFO - Dependencies all met for dep_context=requeueable deps ti=<TaskInstance: check_send_status_dag.check_status scheduled__2023-01-01T00:20:00+00:00 [queued]>
[2024-05-29T13:54:05.761+0000] {taskinstance.py:2306} INFO - Starting attempt 1 of 2
[2024-05-29T13:54:05.932+0000] {taskinstance.py:2330} INFO - Executing <Task(PythonOperator): check_status> on 2023-01-01 00:20:00+00:00
[2024-05-29T13:54:05.944+0000] {standard_task_runner.py:90} INFO - Running: ['airflow', 'tasks', 'run', 'check_send_status_dag', 'check_status', 'scheduled__2023-01-01T00:20:00+00:00', '--job-id', '10', '--raw', '--subdir', 'DAGS_FOLDER/check_send_status_dag.py', '--cfg-path', '/tmp/tmp97jfn5am']
[2024-05-29T13:54:05.948+0000] {standard_task_runner.py:63} INFO - Started process 1123 to run task
[2024-05-29T13:54:05.958+0000] {standard_task_runner.py:91} INFO - Job 10: Subtask check_status
[2024-05-29T13:54:06.178+0000] {task_command.py:426} INFO - Running <TaskInstance: check_send_status_dag.check_status scheduled__2023-01-01T00:20:00+00:00 [running]> on host f708138922bb
[2024-05-29T13:54:06.477+0000] {taskinstance.py:2648} INFO - Exporting env vars: AIRFLOW_CTX_DAG_OWNER='airflow' AIRFLOW_CTX_DAG_ID='check_send_status_dag' AIRFLOW_CTX_TASK_ID='check_status' AIRFLOW_CTX_EXECUTION_DATE='2023-01-01T00:20:00+00:00' AIRFLOW_CTX_TRY_NUMBER='1' AIRFLOW_CTX_DAG_RUN_ID='scheduled__2023-01-01T00:20:00+00:00'
[2024-05-29T13:54:06.479+0000] {taskinstance.py:430} INFO - ::endgroup::
[2024-05-29T13:54:06.551+0000] {check_send_status_dag.py:15} ERROR - Error fetching status: 500 Server Error: INTERNAL SERVER ERROR for url: http://flask:5000/check_send_status
[2024-05-29T13:54:06.555+0000] {taskinstance.py:441} INFO - ::group::Post task execution logs
[2024-05-29T13:54:06.557+0000] {taskinstance.py:2905} ERROR - Task failed with exception
Traceback (most recent call last):
  File "/home/airflow/.local/lib/python3.12/site-packages/airflow/models/taskinstance.py", line 465, in _execute_task
    result = _execute_callable(context=context, **execute_callable_kwargs)
             ^^^^^^^^^^^^^^^^^^^^^^^^^^^^^^^^^^^^^^^^^^^^^^^^^^^^^^^^^^^^^
  File "/home/airflow/.local/lib/python3.12/site-packages/airflow/models/taskinstance.py", line 432, in _execute_callable
    return execute_callable(context=context, **execute_callable_kwargs)
           ^^^^^^^^^^^^^^^^^^^^^^^^^^^^^^^^^^^^^^^^^^^^^^^^^^^^^^^^^^^^
  File "/home/airflow/.local/lib/python3.12/site-packages/airflow/models/baseoperator.py", line 400, in wrapper
    return func(self, *args, **kwargs)
           ^^^^^^^^^^^^^^^^^^^^^^^^^^^
  File "/home/airflow/.local/lib/python3.12/site-packages/airflow/operators/python.py", line 235, in execute
    return_value = self.execute_callable()
                   ^^^^^^^^^^^^^^^^^^^^^^^
  File "/home/airflow/.local/lib/python3.12/site-packages/airflow/operators/python.py", line 252, in execute_callable
    return self.python_callable(*self.op_args, **self.op_kwargs)
           ^^^^^^^^^^^^^^^^^^^^^^^^^^^^^^^^^^^^^^^^^^^^^^^^^^^^^
  File "/opt/airflow/dags/check_send_status_dag.py", line 11, in check_send_status
    response.raise_for_status()
  File "/home/airflow/.local/lib/python3.12/site-packages/requests/models.py", line 1021, in raise_for_status
    raise HTTPError(http_error_msg, response=self)
requests.exceptions.HTTPError: 500 Server Error: INTERNAL SERVER ERROR for url: http://flask:5000/check_send_status
[2024-05-29T13:54:06.594+0000] {taskinstance.py:1206} INFO - Marking task as UP_FOR_RETRY. dag_id=check_send_status_dag, task_id=check_status, run_id=scheduled__2023-01-01T00:20:00+00:00, execution_date=20230101T002000, start_date=20240529T135405, end_date=20240529T135406
[2024-05-29T13:54:06.659+0000] {standard_task_runner.py:110} ERROR - Failed to execute job 10 for task check_status (500 Server Error: INTERNAL SERVER ERROR for url: http://flask:5000/check_send_status; 1123)
[2024-05-29T13:54:06.713+0000] {local_task_job_runner.py:240} INFO - Task exited with return code 1
[2024-05-29T13:54:06.832+0000] {taskinstance.py:3498} INFO - 0 downstream tasks scheduled from follow-on schedule check
[2024-05-29T13:54:06.839+0000] {local_task_job_runner.py:222} INFO - ::endgroup::
[2024-05-29T13:57:19.165+0000] {local_task_job_runner.py:120} INFO - ::group::Pre task execution logs
[2024-05-29T13:57:19.218+0000] {taskinstance.py:2076} INFO - Dependencies all met for dep_context=non-requeueable deps ti=<TaskInstance: check_send_status_dag.check_status scheduled__2023-01-01T00:20:00+00:00 [queued]>
[2024-05-29T13:57:19.241+0000] {taskinstance.py:2076} INFO - Dependencies all met for dep_context=requeueable deps ti=<TaskInstance: check_send_status_dag.check_status scheduled__2023-01-01T00:20:00+00:00 [queued]>
[2024-05-29T13:57:19.242+0000] {taskinstance.py:2306} INFO - Starting attempt 1 of 2
[2024-05-29T13:57:19.303+0000] {taskinstance.py:2330} INFO - Executing <Task(PythonOperator): check_status> on 2023-01-01 00:20:00+00:00
[2024-05-29T13:57:19.312+0000] {standard_task_runner.py:63} INFO - Started process 1164 to run task
[2024-05-29T13:57:19.316+0000] {standard_task_runner.py:90} INFO - Running: ['airflow', 'tasks', 'run', 'check_send_status_dag', 'check_status', 'scheduled__2023-01-01T00:20:00+00:00', '--job-id', '10', '--raw', '--subdir', 'DAGS_FOLDER/check_send_status_dag.py', '--cfg-path', '/tmp/tmp9707y6ao']
[2024-05-29T13:57:19.318+0000] {standard_task_runner.py:91} INFO - Job 10: Subtask check_status
[2024-05-29T13:57:19.450+0000] {task_command.py:426} INFO - Running <TaskInstance: check_send_status_dag.check_status scheduled__2023-01-01T00:20:00+00:00 [running]> on host f708138922bb
[2024-05-29T13:57:19.633+0000] {taskinstance.py:2648} INFO - Exporting env vars: AIRFLOW_CTX_DAG_OWNER='airflow' AIRFLOW_CTX_DAG_ID='check_send_status_dag' AIRFLOW_CTX_TASK_ID='check_status' AIRFLOW_CTX_EXECUTION_DATE='2023-01-01T00:20:00+00:00' AIRFLOW_CTX_TRY_NUMBER='1' AIRFLOW_CTX_DAG_RUN_ID='scheduled__2023-01-01T00:20:00+00:00'
[2024-05-29T13:57:19.634+0000] {taskinstance.py:430} INFO - ::endgroup::
[2024-05-29T13:57:19.667+0000] {check_send_status_dag.py:15} ERROR - Error fetching status: 500 Server Error: INTERNAL SERVER ERROR for url: http://flask:5000/check_send_status
[2024-05-29T13:57:19.668+0000] {taskinstance.py:441} INFO - ::group::Post task execution logs
[2024-05-29T13:57:19.669+0000] {taskinstance.py:2905} ERROR - Task failed with exception
Traceback (most recent call last):
  File "/home/airflow/.local/lib/python3.12/site-packages/airflow/models/taskinstance.py", line 465, in _execute_task
    result = _execute_callable(context=context, **execute_callable_kwargs)
             ^^^^^^^^^^^^^^^^^^^^^^^^^^^^^^^^^^^^^^^^^^^^^^^^^^^^^^^^^^^^^
  File "/home/airflow/.local/lib/python3.12/site-packages/airflow/models/taskinstance.py", line 432, in _execute_callable
    return execute_callable(context=context, **execute_callable_kwargs)
           ^^^^^^^^^^^^^^^^^^^^^^^^^^^^^^^^^^^^^^^^^^^^^^^^^^^^^^^^^^^^
  File "/home/airflow/.local/lib/python3.12/site-packages/airflow/models/baseoperator.py", line 400, in wrapper
    return func(self, *args, **kwargs)
           ^^^^^^^^^^^^^^^^^^^^^^^^^^^
  File "/home/airflow/.local/lib/python3.12/site-packages/airflow/operators/python.py", line 235, in execute
    return_value = self.execute_callable()
                   ^^^^^^^^^^^^^^^^^^^^^^^
  File "/home/airflow/.local/lib/python3.12/site-packages/airflow/operators/python.py", line 252, in execute_callable
    return self.python_callable(*self.op_args, **self.op_kwargs)
           ^^^^^^^^^^^^^^^^^^^^^^^^^^^^^^^^^^^^^^^^^^^^^^^^^^^^^
  File "/opt/airflow/dags/check_send_status_dag.py", line 11, in check_send_status
    response.raise_for_status()
  File "/home/airflow/.local/lib/python3.12/site-packages/requests/models.py", line 1021, in raise_for_status
    raise HTTPError(http_error_msg, response=self)
requests.exceptions.HTTPError: 500 Server Error: INTERNAL SERVER ERROR for url: http://flask:5000/check_send_status
[2024-05-29T13:57:19.691+0000] {taskinstance.py:1206} INFO - Marking task as UP_FOR_RETRY. dag_id=check_send_status_dag, task_id=check_status, run_id=scheduled__2023-01-01T00:20:00+00:00, execution_date=20230101T002000, start_date=20240529T135719, end_date=20240529T135719
[2024-05-29T13:57:19.803+0000] {standard_task_runner.py:110} ERROR - Failed to execute job 10 for task check_status (500 Server Error: INTERNAL SERVER ERROR for url: http://flask:5000/check_send_status; 1164)
[2024-05-29T13:57:19.850+0000] {local_task_job_runner.py:240} INFO - Task exited with return code 1
[2024-05-29T13:57:19.938+0000] {taskinstance.py:3498} INFO - 0 downstream tasks scheduled from follow-on schedule check
[2024-05-29T13:57:19.945+0000] {local_task_job_runner.py:222} INFO - ::endgroup::
[2024-05-29T14:42:41.768+0000] {local_task_job_runner.py:120} INFO - ::group::Pre task execution logs
[2024-05-29T14:42:41.861+0000] {taskinstance.py:2076} INFO - Dependencies all met for dep_context=non-requeueable deps ti=<TaskInstance: check_send_status_dag.check_status scheduled__2023-01-01T00:20:00+00:00 [queued]>
[2024-05-29T14:42:41.881+0000] {taskinstance.py:2076} INFO - Dependencies all met for dep_context=requeueable deps ti=<TaskInstance: check_send_status_dag.check_status scheduled__2023-01-01T00:20:00+00:00 [queued]>
[2024-05-29T14:42:41.882+0000] {taskinstance.py:2306} INFO - Starting attempt 1 of 2
[2024-05-29T14:42:41.938+0000] {taskinstance.py:2330} INFO - Executing <Task(PythonOperator): check_status> on 2023-01-01 00:20:00+00:00
[2024-05-29T14:42:41.945+0000] {standard_task_runner.py:63} INFO - Started process 1576 to run task
[2024-05-29T14:42:41.949+0000] {standard_task_runner.py:90} INFO - Running: ['airflow', 'tasks', 'run', 'check_send_status_dag', 'check_status', 'scheduled__2023-01-01T00:20:00+00:00', '--job-id', '10', '--raw', '--subdir', 'DAGS_FOLDER/check_send_status_dag.py', '--cfg-path', '/tmp/tmpkc1mn_84']
[2024-05-29T14:42:41.951+0000] {standard_task_runner.py:91} INFO - Job 10: Subtask check_status
[2024-05-29T14:42:42.096+0000] {task_command.py:426} INFO - Running <TaskInstance: check_send_status_dag.check_status scheduled__2023-01-01T00:20:00+00:00 [running]> on host f708138922bb
[2024-05-29T14:42:42.618+0000] {taskinstance.py:2648} INFO - Exporting env vars: AIRFLOW_CTX_DAG_OWNER='airflow' AIRFLOW_CTX_DAG_ID='check_send_status_dag' AIRFLOW_CTX_TASK_ID='check_status' AIRFLOW_CTX_EXECUTION_DATE='2023-01-01T00:20:00+00:00' AIRFLOW_CTX_TRY_NUMBER='1' AIRFLOW_CTX_DAG_RUN_ID='scheduled__2023-01-01T00:20:00+00:00'
[2024-05-29T14:42:42.620+0000] {taskinstance.py:430} INFO - ::endgroup::
[2024-05-29T14:42:42.668+0000] {check_send_status_dag.py:13} INFO - Status: {'status': 'unknown'}
[2024-05-29T14:42:42.671+0000] {python.py:237} INFO - Done. Returned value was: None
[2024-05-29T14:42:42.674+0000] {taskinstance.py:441} INFO - ::group::Post task execution logs
[2024-05-29T14:42:42.700+0000] {taskinstance.py:1206} INFO - Marking task as SUCCESS. dag_id=check_send_status_dag, task_id=check_status, run_id=scheduled__2023-01-01T00:20:00+00:00, execution_date=20230101T002000, start_date=20240529T144241, end_date=20240529T144242
[2024-05-29T14:42:42.768+0000] {local_task_job_runner.py:240} INFO - Task exited with return code 0
[2024-05-29T14:42:42.818+0000] {taskinstance.py:3498} INFO - 0 downstream tasks scheduled from follow-on schedule check
[2024-05-29T14:42:42.838+0000] {local_task_job_runner.py:222} INFO - ::endgroup::
