[2024-05-29T10:45:19.827+0000] {local_task_job_runner.py:120} INFO - ::group::Pre task execution logs
[2024-05-29T10:45:19.880+0000] {taskinstance.py:2076} INFO - Dependencies all met for dep_context=non-requeueable deps ti=<TaskInstance: check_send_status_dag.check_status scheduled__2023-01-01T02:10:00+00:00 [queued]>
[2024-05-29T10:45:19.904+0000] {taskinstance.py:2076} INFO - Dependencies all met for dep_context=requeueable deps ti=<TaskInstance: check_send_status_dag.check_status scheduled__2023-01-01T02:10:00+00:00 [queued]>
[2024-05-29T10:45:19.905+0000] {taskinstance.py:2306} INFO - Starting attempt 1 of 2
[2024-05-29T10:45:19.971+0000] {taskinstance.py:2330} INFO - Executing <Task(PythonOperator): check_status> on 2023-01-01 02:10:00+00:00
[2024-05-29T10:45:19.976+0000] {standard_task_runner.py:63} INFO - Started process 141 to run task
[2024-05-29T10:45:19.980+0000] {standard_task_runner.py:90} INFO - Running: ['airflow', 'tasks', 'run', 'check_send_status_dag', 'check_status', 'scheduled__2023-01-01T02:10:00+00:00', '--job-id', '21', '--raw', '--subdir', 'DAGS_FOLDER/check_send_status_dag.py', '--cfg-path', '/tmp/tmpz9o631oc']
[2024-05-29T10:45:19.984+0000] {standard_task_runner.py:91} INFO - Job 21: Subtask check_status
[2024-05-29T10:45:20.156+0000] {task_command.py:426} INFO - Running <TaskInstance: check_send_status_dag.check_status scheduled__2023-01-01T02:10:00+00:00 [running]> on host f708138922bb
[2024-05-29T10:45:20.544+0000] {taskinstance.py:2648} INFO - Exporting env vars: AIRFLOW_CTX_DAG_OWNER='airflow' AIRFLOW_CTX_DAG_ID='check_send_status_dag' AIRFLOW_CTX_TASK_ID='check_status' AIRFLOW_CTX_EXECUTION_DATE='2023-01-01T02:10:00+00:00' AIRFLOW_CTX_TRY_NUMBER='1' AIRFLOW_CTX_DAG_RUN_ID='scheduled__2023-01-01T02:10:00+00:00'
[2024-05-29T10:45:20.546+0000] {taskinstance.py:430} INFO - ::endgroup::
[2024-05-29T10:45:21.152+0000] {check_send_status_dag.py:15} ERROR - Error fetching status: 404 Client Error: Not Found for url: http://host.docker.internal/check_send_status
[2024-05-29T10:45:21.153+0000] {taskinstance.py:441} INFO - ::group::Post task execution logs
[2024-05-29T10:45:21.154+0000] {taskinstance.py:2905} ERROR - Task failed with exception
Traceback (most recent call last):
  File "/home/airflow/.local/lib/python3.12/site-packages/airflow/models/taskinstance.py", line 465, in _execute_task
    result = _execute_callable(context=context, **execute_callable_kwargs)
             ^^^^^^^^^^^^^^^^^^^^^^^^^^^^^^^^^^^^^^^^^^^^^^^^^^^^^^^^^^^^^
  File "/home/airflow/.local/lib/python3.12/site-packages/airflow/models/taskinstance.py", line 432, in _execute_callable
    return execute_callable(context=context, **execute_callable_kwargs)
           ^^^^^^^^^^^^^^^^^^^^^^^^^^^^^^^^^^^^^^^^^^^^^^^^^^^^^^^^^^^^
  File "/home/airflow/.local/lib/python3.12/site-packages/airflow/models/baseoperator.py", line 400, in wrapper
    return func(self, *args, **kwargs)
           ^^^^^^^^^^^^^^^^^^^^^^^^^^^
  File "/home/airflow/.local/lib/python3.12/site-packages/airflow/operators/python.py", line 235, in execute
    return_value = self.execute_callable()
                   ^^^^^^^^^^^^^^^^^^^^^^^
  File "/home/airflow/.local/lib/python3.12/site-packages/airflow/operators/python.py", line 252, in execute_callable
    return self.python_callable(*self.op_args, **self.op_kwargs)
           ^^^^^^^^^^^^^^^^^^^^^^^^^^^^^^^^^^^^^^^^^^^^^^^^^^^^^
  File "/opt/airflow/dags/check_send_status_dag.py", line 11, in check_send_status
    response.raise_for_status()
  File "/home/airflow/.local/lib/python3.12/site-packages/requests/models.py", line 1021, in raise_for_status
    raise HTTPError(http_error_msg, response=self)
requests.exceptions.HTTPError: 404 Client Error: Not Found for url: http://host.docker.internal/check_send_status
[2024-05-29T10:45:21.177+0000] {taskinstance.py:1206} INFO - Marking task as UP_FOR_RETRY. dag_id=check_send_status_dag, task_id=check_status, run_id=scheduled__2023-01-01T02:10:00+00:00, execution_date=20230101T021000, start_date=20240529T104519, end_date=20240529T104521
[2024-05-29T10:45:21.271+0000] {standard_task_runner.py:110} ERROR - Failed to execute job 21 for task check_status (404 Client Error: Not Found for url: http://host.docker.internal/check_send_status; 141)
[2024-05-29T10:45:21.284+0000] {local_task_job_runner.py:240} INFO - Task exited with return code 1
[2024-05-29T10:45:21.313+0000] {taskinstance.py:3498} INFO - 0 downstream tasks scheduled from follow-on schedule check
[2024-05-29T10:45:21.316+0000] {local_task_job_runner.py:222} INFO - ::endgroup::
[2024-05-29T13:58:52.833+0000] {local_task_job_runner.py:120} INFO - ::group::Pre task execution logs
[2024-05-29T13:58:52.880+0000] {taskinstance.py:2076} INFO - Dependencies all met for dep_context=non-requeueable deps ti=<TaskInstance: check_send_status_dag.check_status scheduled__2023-01-01T02:10:00+00:00 [queued]>
[2024-05-29T13:58:52.900+0000] {taskinstance.py:2076} INFO - Dependencies all met for dep_context=requeueable deps ti=<TaskInstance: check_send_status_dag.check_status scheduled__2023-01-01T02:10:00+00:00 [queued]>
[2024-05-29T13:58:52.901+0000] {taskinstance.py:2306} INFO - Starting attempt 1 of 2
[2024-05-29T13:58:52.959+0000] {taskinstance.py:2330} INFO - Executing <Task(PythonOperator): check_status> on 2023-01-01 02:10:00+00:00
[2024-05-29T13:58:52.966+0000] {standard_task_runner.py:63} INFO - Started process 1221 to run task
[2024-05-29T13:58:52.969+0000] {standard_task_runner.py:90} INFO - Running: ['airflow', 'tasks', 'run', 'check_send_status_dag', 'check_status', 'scheduled__2023-01-01T02:10:00+00:00', '--job-id', '21', '--raw', '--subdir', 'DAGS_FOLDER/check_send_status_dag.py', '--cfg-path', '/tmp/tmp7b16nkva']
[2024-05-29T13:58:52.972+0000] {standard_task_runner.py:91} INFO - Job 21: Subtask check_status
[2024-05-29T13:58:53.089+0000] {task_command.py:426} INFO - Running <TaskInstance: check_send_status_dag.check_status scheduled__2023-01-01T02:10:00+00:00 [running]> on host f708138922bb
[2024-05-29T13:58:53.288+0000] {taskinstance.py:2648} INFO - Exporting env vars: AIRFLOW_CTX_DAG_OWNER='airflow' AIRFLOW_CTX_DAG_ID='check_send_status_dag' AIRFLOW_CTX_TASK_ID='check_status' AIRFLOW_CTX_EXECUTION_DATE='2023-01-01T02:10:00+00:00' AIRFLOW_CTX_TRY_NUMBER='1' AIRFLOW_CTX_DAG_RUN_ID='scheduled__2023-01-01T02:10:00+00:00'
[2024-05-29T13:58:53.290+0000] {taskinstance.py:430} INFO - ::endgroup::
[2024-05-29T13:58:53.346+0000] {check_send_status_dag.py:15} ERROR - Error fetching status: 500 Server Error: INTERNAL SERVER ERROR for url: http://flask:5000/check_send_status
[2024-05-29T13:58:53.348+0000] {taskinstance.py:441} INFO - ::group::Post task execution logs
[2024-05-29T13:58:53.349+0000] {taskinstance.py:2905} ERROR - Task failed with exception
Traceback (most recent call last):
  File "/home/airflow/.local/lib/python3.12/site-packages/airflow/models/taskinstance.py", line 465, in _execute_task
    result = _execute_callable(context=context, **execute_callable_kwargs)
             ^^^^^^^^^^^^^^^^^^^^^^^^^^^^^^^^^^^^^^^^^^^^^^^^^^^^^^^^^^^^^
  File "/home/airflow/.local/lib/python3.12/site-packages/airflow/models/taskinstance.py", line 432, in _execute_callable
    return execute_callable(context=context, **execute_callable_kwargs)
           ^^^^^^^^^^^^^^^^^^^^^^^^^^^^^^^^^^^^^^^^^^^^^^^^^^^^^^^^^^^^
  File "/home/airflow/.local/lib/python3.12/site-packages/airflow/models/baseoperator.py", line 400, in wrapper
    return func(self, *args, **kwargs)
           ^^^^^^^^^^^^^^^^^^^^^^^^^^^
  File "/home/airflow/.local/lib/python3.12/site-packages/airflow/operators/python.py", line 235, in execute
    return_value = self.execute_callable()
                   ^^^^^^^^^^^^^^^^^^^^^^^
  File "/home/airflow/.local/lib/python3.12/site-packages/airflow/operators/python.py", line 252, in execute_callable
    return self.python_callable(*self.op_args, **self.op_kwargs)
           ^^^^^^^^^^^^^^^^^^^^^^^^^^^^^^^^^^^^^^^^^^^^^^^^^^^^^
  File "/opt/airflow/dags/check_send_status_dag.py", line 11, in check_send_status
    response.raise_for_status()
  File "/home/airflow/.local/lib/python3.12/site-packages/requests/models.py", line 1021, in raise_for_status
    raise HTTPError(http_error_msg, response=self)
requests.exceptions.HTTPError: 500 Server Error: INTERNAL SERVER ERROR for url: http://flask:5000/check_send_status
[2024-05-29T13:58:53.378+0000] {taskinstance.py:1206} INFO - Marking task as UP_FOR_RETRY. dag_id=check_send_status_dag, task_id=check_status, run_id=scheduled__2023-01-01T02:10:00+00:00, execution_date=20230101T021000, start_date=20240529T135852, end_date=20240529T135853
[2024-05-29T13:58:53.453+0000] {standard_task_runner.py:110} ERROR - Failed to execute job 21 for task check_status (500 Server Error: INTERNAL SERVER ERROR for url: http://flask:5000/check_send_status; 1221)
[2024-05-29T13:58:53.503+0000] {local_task_job_runner.py:240} INFO - Task exited with return code 1
[2024-05-29T13:58:53.529+0000] {taskinstance.py:3498} INFO - 0 downstream tasks scheduled from follow-on schedule check
[2024-05-29T13:58:53.531+0000] {local_task_job_runner.py:222} INFO - ::endgroup::
[2024-05-29T14:45:29.838+0000] {local_task_job_runner.py:120} INFO - ::group::Pre task execution logs
[2024-05-29T14:45:29.972+0000] {taskinstance.py:2076} INFO - Dependencies all met for dep_context=non-requeueable deps ti=<TaskInstance: check_send_status_dag.check_status scheduled__2023-01-01T02:10:00+00:00 [queued]>
[2024-05-29T14:45:29.999+0000] {taskinstance.py:2076} INFO - Dependencies all met for dep_context=requeueable deps ti=<TaskInstance: check_send_status_dag.check_status scheduled__2023-01-01T02:10:00+00:00 [queued]>
[2024-05-29T14:45:30.000+0000] {taskinstance.py:2306} INFO - Starting attempt 1 of 2
[2024-05-29T14:45:30.238+0000] {taskinstance.py:2330} INFO - Executing <Task(PythonOperator): check_status> on 2023-01-01 02:10:00+00:00
[2024-05-29T14:45:30.254+0000] {standard_task_runner.py:63} INFO - Started process 1635 to run task
[2024-05-29T14:45:30.259+0000] {standard_task_runner.py:90} INFO - Running: ['airflow', 'tasks', 'run', 'check_send_status_dag', 'check_status', 'scheduled__2023-01-01T02:10:00+00:00', '--job-id', '21', '--raw', '--subdir', 'DAGS_FOLDER/check_send_status_dag.py', '--cfg-path', '/tmp/tmp54k6iexd']
[2024-05-29T14:45:30.275+0000] {standard_task_runner.py:91} INFO - Job 21: Subtask check_status
[2024-05-29T14:45:30.698+0000] {task_command.py:426} INFO - Running <TaskInstance: check_send_status_dag.check_status scheduled__2023-01-01T02:10:00+00:00 [running]> on host f708138922bb
[2024-05-29T14:45:31.230+0000] {taskinstance.py:2648} INFO - Exporting env vars: AIRFLOW_CTX_DAG_OWNER='airflow' AIRFLOW_CTX_DAG_ID='check_send_status_dag' AIRFLOW_CTX_TASK_ID='check_status' AIRFLOW_CTX_EXECUTION_DATE='2023-01-01T02:10:00+00:00' AIRFLOW_CTX_TRY_NUMBER='1' AIRFLOW_CTX_DAG_RUN_ID='scheduled__2023-01-01T02:10:00+00:00'
[2024-05-29T14:45:31.231+0000] {taskinstance.py:430} INFO - ::endgroup::
[2024-05-29T14:45:31.266+0000] {check_send_status_dag.py:13} INFO - Status: {'status': 'success'}
[2024-05-29T14:45:31.268+0000] {python.py:237} INFO - Done. Returned value was: None
[2024-05-29T14:45:31.270+0000] {taskinstance.py:441} INFO - ::group::Post task execution logs
[2024-05-29T14:45:31.289+0000] {taskinstance.py:1206} INFO - Marking task as SUCCESS. dag_id=check_send_status_dag, task_id=check_status, run_id=scheduled__2023-01-01T02:10:00+00:00, execution_date=20230101T021000, start_date=20240529T144529, end_date=20240529T144531
[2024-05-29T14:45:31.381+0000] {local_task_job_runner.py:240} INFO - Task exited with return code 0
[2024-05-29T14:45:31.409+0000] {taskinstance.py:3498} INFO - 0 downstream tasks scheduled from follow-on schedule check
[2024-05-29T14:45:31.412+0000] {local_task_job_runner.py:222} INFO - ::endgroup::
