[2024-05-29T13:07:55.451+0000] {local_task_job_runner.py:120} INFO - ::group::Pre task execution logs
[2024-05-29T13:07:55.553+0000] {taskinstance.py:2076} INFO - Dependencies all met for dep_context=non-requeueable deps ti=<TaskInstance: check_send_status_dag.check_status scheduled__2023-01-01T08:50:00+00:00 [queued]>
[2024-05-29T13:07:55.588+0000] {taskinstance.py:2076} INFO - Dependencies all met for dep_context=requeueable deps ti=<TaskInstance: check_send_status_dag.check_status scheduled__2023-01-01T08:50:00+00:00 [queued]>
[2024-05-29T13:07:55.589+0000] {taskinstance.py:2306} INFO - Starting attempt 1 of 2
[2024-05-29T13:07:55.694+0000] {taskinstance.py:2330} INFO - Executing <Task(PythonOperator): check_status> on 2023-01-01 08:50:00+00:00
[2024-05-29T13:07:55.706+0000] {standard_task_runner.py:90} INFO - Running: ['airflow', 'tasks', 'run', 'check_send_status_dag', 'check_status', 'scheduled__2023-01-01T08:50:00+00:00', '--job-id', '111', '--raw', '--subdir', 'DAGS_FOLDER/check_send_status_dag.py', '--cfg-path', '/tmp/tmpekh2e_ny']
[2024-05-29T13:07:55.709+0000] {standard_task_runner.py:91} INFO - Job 111: Subtask check_status
[2024-05-29T13:07:55.711+0000] {standard_task_runner.py:63} INFO - Started process 625 to run task
[2024-05-29T13:07:56.473+0000] {task_command.py:426} INFO - Running <TaskInstance: check_send_status_dag.check_status scheduled__2023-01-01T08:50:00+00:00 [running]> on host f708138922bb
[2024-05-29T13:07:57.036+0000] {taskinstance.py:2648} INFO - Exporting env vars: AIRFLOW_CTX_DAG_OWNER='airflow' AIRFLOW_CTX_DAG_ID='check_send_status_dag' AIRFLOW_CTX_TASK_ID='check_status' AIRFLOW_CTX_EXECUTION_DATE='2023-01-01T08:50:00+00:00' AIRFLOW_CTX_TRY_NUMBER='1' AIRFLOW_CTX_DAG_RUN_ID='scheduled__2023-01-01T08:50:00+00:00'
[2024-05-29T13:07:57.038+0000] {taskinstance.py:430} INFO - ::endgroup::
[2024-05-29T13:07:57.110+0000] {check_send_status_dag.py:15} ERROR - Error fetching status: HTTPConnectionPool(host='127.0.0.1', port=5000): Max retries exceeded with url: /check_send_status (Caused by NewConnectionError('<urllib3.connection.HTTPConnection object at 0x7f7aac98c800>: Failed to establish a new connection: [Errno 111] Connection refused'))
[2024-05-29T13:07:57.133+0000] {taskinstance.py:441} INFO - ::group::Post task execution logs
[2024-05-29T13:07:57.135+0000] {taskinstance.py:2905} ERROR - Task failed with exception
Traceback (most recent call last):
  File "/home/airflow/.local/lib/python3.12/site-packages/urllib3/connection.py", line 198, in _new_conn
    sock = connection.create_connection(
           ^^^^^^^^^^^^^^^^^^^^^^^^^^^^^
  File "/home/airflow/.local/lib/python3.12/site-packages/urllib3/util/connection.py", line 85, in create_connection
    raise err
  File "/home/airflow/.local/lib/python3.12/site-packages/urllib3/util/connection.py", line 73, in create_connection
    sock.connect(sa)
ConnectionRefusedError: [Errno 111] Connection refused

The above exception was the direct cause of the following exception:

Traceback (most recent call last):
  File "/home/airflow/.local/lib/python3.12/site-packages/urllib3/connectionpool.py", line 793, in urlopen
    response = self._make_request(
               ^^^^^^^^^^^^^^^^^^^
  File "/home/airflow/.local/lib/python3.12/site-packages/urllib3/connectionpool.py", line 496, in _make_request
    conn.request(
  File "/home/airflow/.local/lib/python3.12/site-packages/urllib3/connection.py", line 400, in request
    self.endheaders()
  File "/usr/local/lib/python3.12/http/client.py", line 1331, in endheaders
    self._send_output(message_body, encode_chunked=encode_chunked)
  File "/usr/local/lib/python3.12/http/client.py", line 1091, in _send_output
    self.send(msg)
  File "/usr/local/lib/python3.12/http/client.py", line 1035, in send
    self.connect()
  File "/home/airflow/.local/lib/python3.12/site-packages/urllib3/connection.py", line 238, in connect
    self.sock = self._new_conn()
                ^^^^^^^^^^^^^^^^
  File "/home/airflow/.local/lib/python3.12/site-packages/urllib3/connection.py", line 213, in _new_conn
    raise NewConnectionError(
urllib3.exceptions.NewConnectionError: <urllib3.connection.HTTPConnection object at 0x7f7aac98c800>: Failed to establish a new connection: [Errno 111] Connection refused

The above exception was the direct cause of the following exception:

Traceback (most recent call last):
  File "/home/airflow/.local/lib/python3.12/site-packages/requests/adapters.py", line 486, in send
    resp = conn.urlopen(
           ^^^^^^^^^^^^^
  File "/home/airflow/.local/lib/python3.12/site-packages/urllib3/connectionpool.py", line 847, in urlopen
    retries = retries.increment(
              ^^^^^^^^^^^^^^^^^^
  File "/home/airflow/.local/lib/python3.12/site-packages/urllib3/util/retry.py", line 515, in increment
    raise MaxRetryError(_pool, url, reason) from reason  # type: ignore[arg-type]
    ^^^^^^^^^^^^^^^^^^^^^^^^^^^^^^^^^^^^^^^^^^^^^^^^^^^
urllib3.exceptions.MaxRetryError: HTTPConnectionPool(host='127.0.0.1', port=5000): Max retries exceeded with url: /check_send_status (Caused by NewConnectionError('<urllib3.connection.HTTPConnection object at 0x7f7aac98c800>: Failed to establish a new connection: [Errno 111] Connection refused'))

During handling of the above exception, another exception occurred:

Traceback (most recent call last):
  File "/home/airflow/.local/lib/python3.12/site-packages/airflow/models/taskinstance.py", line 465, in _execute_task
    result = _execute_callable(context=context, **execute_callable_kwargs)
             ^^^^^^^^^^^^^^^^^^^^^^^^^^^^^^^^^^^^^^^^^^^^^^^^^^^^^^^^^^^^^
  File "/home/airflow/.local/lib/python3.12/site-packages/airflow/models/taskinstance.py", line 432, in _execute_callable
    return execute_callable(context=context, **execute_callable_kwargs)
           ^^^^^^^^^^^^^^^^^^^^^^^^^^^^^^^^^^^^^^^^^^^^^^^^^^^^^^^^^^^^
  File "/home/airflow/.local/lib/python3.12/site-packages/airflow/models/baseoperator.py", line 400, in wrapper
    return func(self, *args, **kwargs)
           ^^^^^^^^^^^^^^^^^^^^^^^^^^^
  File "/home/airflow/.local/lib/python3.12/site-packages/airflow/operators/python.py", line 235, in execute
    return_value = self.execute_callable()
                   ^^^^^^^^^^^^^^^^^^^^^^^
  File "/home/airflow/.local/lib/python3.12/site-packages/airflow/operators/python.py", line 252, in execute_callable
    return self.python_callable(*self.op_args, **self.op_kwargs)
           ^^^^^^^^^^^^^^^^^^^^^^^^^^^^^^^^^^^^^^^^^^^^^^^^^^^^^
  File "/opt/airflow/dags/check_send_status_dag.py", line 10, in check_send_status
    response = requests.get("http://127.0.0.1:5000/check_send_status")
               ^^^^^^^^^^^^^^^^^^^^^^^^^^^^^^^^^^^^^^^^^^^^^^^^^^^^^^^
  File "/home/airflow/.local/lib/python3.12/site-packages/requests/api.py", line 73, in get
    return request("get", url, params=params, **kwargs)
           ^^^^^^^^^^^^^^^^^^^^^^^^^^^^^^^^^^^^^^^^^^^^
  File "/home/airflow/.local/lib/python3.12/site-packages/requests/api.py", line 59, in request
    return session.request(method=method, url=url, **kwargs)
           ^^^^^^^^^^^^^^^^^^^^^^^^^^^^^^^^^^^^^^^^^^^^^^^^^
  File "/home/airflow/.local/lib/python3.12/site-packages/requests/sessions.py", line 589, in request
    resp = self.send(prep, **send_kwargs)
           ^^^^^^^^^^^^^^^^^^^^^^^^^^^^^^
  File "/home/airflow/.local/lib/python3.12/site-packages/requests/sessions.py", line 703, in send
    r = adapter.send(request, **kwargs)
        ^^^^^^^^^^^^^^^^^^^^^^^^^^^^^^^
  File "/home/airflow/.local/lib/python3.12/site-packages/requests/adapters.py", line 519, in send
    raise ConnectionError(e, request=request)
requests.exceptions.ConnectionError: HTTPConnectionPool(host='127.0.0.1', port=5000): Max retries exceeded with url: /check_send_status (Caused by NewConnectionError('<urllib3.connection.HTTPConnection object at 0x7f7aac98c800>: Failed to establish a new connection: [Errno 111] Connection refused'))
[2024-05-29T13:07:57.207+0000] {taskinstance.py:1206} INFO - Marking task as UP_FOR_RETRY. dag_id=check_send_status_dag, task_id=check_status, run_id=scheduled__2023-01-01T08:50:00+00:00, execution_date=20230101T085000, start_date=20240529T130755, end_date=20240529T130757
[2024-05-29T13:07:57.316+0000] {standard_task_runner.py:110} ERROR - Failed to execute job 111 for task check_status (HTTPConnectionPool(host='127.0.0.1', port=5000): Max retries exceeded with url: /check_send_status (Caused by NewConnectionError('<urllib3.connection.HTTPConnection object at 0x7f7aac98c800>: Failed to establish a new connection: [Errno 111] Connection refused')); 625)
[2024-05-29T13:07:57.346+0000] {local_task_job_runner.py:240} INFO - Task exited with return code 1
[2024-05-29T13:07:57.387+0000] {taskinstance.py:3498} INFO - 0 downstream tasks scheduled from follow-on schedule check
[2024-05-29T13:07:57.392+0000] {local_task_job_runner.py:222} INFO - ::endgroup::
[2024-05-29T15:08:05.224+0000] {local_task_job_runner.py:120} INFO - ::group::Pre task execution logs
[2024-05-29T15:08:05.418+0000] {taskinstance.py:2076} INFO - Dependencies all met for dep_context=non-requeueable deps ti=<TaskInstance: check_send_status_dag.check_status scheduled__2023-01-01T08:50:00+00:00 [queued]>
[2024-05-29T15:08:05.479+0000] {taskinstance.py:2076} INFO - Dependencies all met for dep_context=requeueable deps ti=<TaskInstance: check_send_status_dag.check_status scheduled__2023-01-01T08:50:00+00:00 [queued]>
[2024-05-29T15:08:05.480+0000] {taskinstance.py:2306} INFO - Starting attempt 1 of 2
[2024-05-29T15:08:05.663+0000] {taskinstance.py:2330} INFO - Executing <Task(PythonOperator): check_status> on 2023-01-01 08:50:00+00:00
[2024-05-29T15:08:05.675+0000] {standard_task_runner.py:90} INFO - Running: ['airflow', 'tasks', 'run', 'check_send_status_dag', 'check_status', 'scheduled__2023-01-01T08:50:00+00:00', '--job-id', '81', '--raw', '--subdir', 'DAGS_FOLDER/check_send_status_dag.py', '--cfg-path', '/tmp/tmp2j6j5p16']
[2024-05-29T15:08:05.670+0000] {standard_task_runner.py:63} INFO - Started process 179 to run task
[2024-05-29T15:08:05.687+0000] {standard_task_runner.py:91} INFO - Job 81: Subtask check_status
[2024-05-29T15:08:06.341+0000] {task_command.py:426} INFO - Running <TaskInstance: check_send_status_dag.check_status scheduled__2023-01-01T08:50:00+00:00 [running]> on host f708138922bb
[2024-05-29T15:08:07.784+0000] {taskinstance.py:2648} INFO - Exporting env vars: AIRFLOW_CTX_DAG_OWNER='airflow' AIRFLOW_CTX_DAG_ID='check_send_status_dag' AIRFLOW_CTX_TASK_ID='check_status' AIRFLOW_CTX_EXECUTION_DATE='2023-01-01T08:50:00+00:00' AIRFLOW_CTX_TRY_NUMBER='1' AIRFLOW_CTX_DAG_RUN_ID='scheduled__2023-01-01T08:50:00+00:00'
[2024-05-29T15:08:07.785+0000] {taskinstance.py:430} INFO - ::endgroup::
[2024-05-29T15:08:07.841+0000] {check_send_status_dag.py:15} ERROR - Error fetching status: 500 Server Error: INTERNAL SERVER ERROR for url: http://flask:5000/check_send_status
[2024-05-29T15:08:07.843+0000] {taskinstance.py:441} INFO - ::group::Post task execution logs
[2024-05-29T15:08:07.854+0000] {taskinstance.py:2905} ERROR - Task failed with exception
Traceback (most recent call last):
  File "/home/airflow/.local/lib/python3.12/site-packages/airflow/models/taskinstance.py", line 465, in _execute_task
    result = _execute_callable(context=context, **execute_callable_kwargs)
             ^^^^^^^^^^^^^^^^^^^^^^^^^^^^^^^^^^^^^^^^^^^^^^^^^^^^^^^^^^^^^
  File "/home/airflow/.local/lib/python3.12/site-packages/airflow/models/taskinstance.py", line 432, in _execute_callable
    return execute_callable(context=context, **execute_callable_kwargs)
           ^^^^^^^^^^^^^^^^^^^^^^^^^^^^^^^^^^^^^^^^^^^^^^^^^^^^^^^^^^^^
  File "/home/airflow/.local/lib/python3.12/site-packages/airflow/models/baseoperator.py", line 400, in wrapper
    return func(self, *args, **kwargs)
           ^^^^^^^^^^^^^^^^^^^^^^^^^^^
  File "/home/airflow/.local/lib/python3.12/site-packages/airflow/operators/python.py", line 235, in execute
    return_value = self.execute_callable()
                   ^^^^^^^^^^^^^^^^^^^^^^^
  File "/home/airflow/.local/lib/python3.12/site-packages/airflow/operators/python.py", line 252, in execute_callable
    return self.python_callable(*self.op_args, **self.op_kwargs)
           ^^^^^^^^^^^^^^^^^^^^^^^^^^^^^^^^^^^^^^^^^^^^^^^^^^^^^
  File "/opt/airflow/dags/check_send_status_dag.py", line 11, in check_send_status
    response.raise_for_status()
  File "/home/airflow/.local/lib/python3.12/site-packages/requests/models.py", line 1021, in raise_for_status
    raise HTTPError(http_error_msg, response=self)
requests.exceptions.HTTPError: 500 Server Error: INTERNAL SERVER ERROR for url: http://flask:5000/check_send_status
[2024-05-29T15:08:07.916+0000] {taskinstance.py:1206} INFO - Marking task as UP_FOR_RETRY. dag_id=check_send_status_dag, task_id=check_status, run_id=scheduled__2023-01-01T08:50:00+00:00, execution_date=20230101T085000, start_date=20240529T150805, end_date=20240529T150807
[2024-05-29T15:08:07.982+0000] {standard_task_runner.py:110} ERROR - Failed to execute job 81 for task check_status (500 Server Error: INTERNAL SERVER ERROR for url: http://flask:5000/check_send_status; 179)
[2024-05-29T15:08:08.039+0000] {local_task_job_runner.py:240} INFO - Task exited with return code 1
[2024-05-29T15:08:08.075+0000] {taskinstance.py:3498} INFO - 0 downstream tasks scheduled from follow-on schedule check
[2024-05-29T15:08:08.078+0000] {local_task_job_runner.py:222} INFO - ::endgroup::
