[2024-05-29T10:42:48.779+0000] {local_task_job_runner.py:120} INFO - ::group::Pre task execution logs
[2024-05-29T10:42:48.835+0000] {taskinstance.py:2076} INFO - Dependencies all met for dep_context=non-requeueable deps ti=<TaskInstance: check_send_status_dag.check_status scheduled__2023-01-01T00:10:00+00:00 [queued]>
[2024-05-29T10:42:48.859+0000] {taskinstance.py:2076} INFO - Dependencies all met for dep_context=requeueable deps ti=<TaskInstance: check_send_status_dag.check_status scheduled__2023-01-01T00:10:00+00:00 [queued]>
[2024-05-29T10:42:48.860+0000] {taskinstance.py:2306} INFO - Starting attempt 1 of 2
[2024-05-29T10:42:48.923+0000] {taskinstance.py:2330} INFO - Executing <Task(PythonOperator): check_status> on 2023-01-01 00:10:00+00:00
[2024-05-29T10:42:48.929+0000] {standard_task_runner.py:63} INFO - Started process 77 to run task
[2024-05-29T10:42:48.932+0000] {standard_task_runner.py:90} INFO - Running: ['airflow', 'tasks', 'run', 'check_send_status_dag', 'check_status', 'scheduled__2023-01-01T00:10:00+00:00', '--job-id', '9', '--raw', '--subdir', 'DAGS_FOLDER/check_send_status_dag.py', '--cfg-path', '/tmp/tmpes7zjals']
[2024-05-29T10:42:48.935+0000] {standard_task_runner.py:91} INFO - Job 9: Subtask check_status
[2024-05-29T10:42:49.050+0000] {task_command.py:426} INFO - Running <TaskInstance: check_send_status_dag.check_status scheduled__2023-01-01T00:10:00+00:00 [running]> on host f708138922bb
[2024-05-29T10:42:49.214+0000] {taskinstance.py:2648} INFO - Exporting env vars: AIRFLOW_CTX_DAG_OWNER='airflow' AIRFLOW_CTX_DAG_ID='check_send_status_dag' AIRFLOW_CTX_TASK_ID='check_status' AIRFLOW_CTX_EXECUTION_DATE='2023-01-01T00:10:00+00:00' AIRFLOW_CTX_TRY_NUMBER='1' AIRFLOW_CTX_DAG_RUN_ID='scheduled__2023-01-01T00:10:00+00:00'
[2024-05-29T10:42:49.215+0000] {taskinstance.py:430} INFO - ::endgroup::
[2024-05-29T10:42:49.235+0000] {check_send_status_dag.py:15} ERROR - Error fetching status: HTTPConnectionPool(host='127.0.0.1', port=5000): Max retries exceeded with url: /check_send_status (Caused by NewConnectionError('<urllib3.connection.HTTPConnection object at 0x7f724cef4f80>: Failed to establish a new connection: [Errno 111] Connection refused'))
[2024-05-29T10:42:49.235+0000] {taskinstance.py:441} INFO - ::group::Post task execution logs
[2024-05-29T10:42:49.236+0000] {taskinstance.py:2905} ERROR - Task failed with exception
Traceback (most recent call last):
  File "/home/airflow/.local/lib/python3.12/site-packages/urllib3/connection.py", line 198, in _new_conn
    sock = connection.create_connection(
           ^^^^^^^^^^^^^^^^^^^^^^^^^^^^^
  File "/home/airflow/.local/lib/python3.12/site-packages/urllib3/util/connection.py", line 85, in create_connection
    raise err
  File "/home/airflow/.local/lib/python3.12/site-packages/urllib3/util/connection.py", line 73, in create_connection
    sock.connect(sa)
ConnectionRefusedError: [Errno 111] Connection refused

The above exception was the direct cause of the following exception:

Traceback (most recent call last):
  File "/home/airflow/.local/lib/python3.12/site-packages/urllib3/connectionpool.py", line 793, in urlopen
    response = self._make_request(
               ^^^^^^^^^^^^^^^^^^^
  File "/home/airflow/.local/lib/python3.12/site-packages/urllib3/connectionpool.py", line 496, in _make_request
    conn.request(
  File "/home/airflow/.local/lib/python3.12/site-packages/urllib3/connection.py", line 400, in request
    self.endheaders()
  File "/usr/local/lib/python3.12/http/client.py", line 1331, in endheaders
    self._send_output(message_body, encode_chunked=encode_chunked)
  File "/usr/local/lib/python3.12/http/client.py", line 1091, in _send_output
    self.send(msg)
  File "/usr/local/lib/python3.12/http/client.py", line 1035, in send
    self.connect()
  File "/home/airflow/.local/lib/python3.12/site-packages/urllib3/connection.py", line 238, in connect
    self.sock = self._new_conn()
                ^^^^^^^^^^^^^^^^
  File "/home/airflow/.local/lib/python3.12/site-packages/urllib3/connection.py", line 213, in _new_conn
    raise NewConnectionError(
urllib3.exceptions.NewConnectionError: <urllib3.connection.HTTPConnection object at 0x7f724cef4f80>: Failed to establish a new connection: [Errno 111] Connection refused

The above exception was the direct cause of the following exception:

Traceback (most recent call last):
  File "/home/airflow/.local/lib/python3.12/site-packages/requests/adapters.py", line 486, in send
    resp = conn.urlopen(
           ^^^^^^^^^^^^^
  File "/home/airflow/.local/lib/python3.12/site-packages/urllib3/connectionpool.py", line 847, in urlopen
    retries = retries.increment(
              ^^^^^^^^^^^^^^^^^^
  File "/home/airflow/.local/lib/python3.12/site-packages/urllib3/util/retry.py", line 515, in increment
    raise MaxRetryError(_pool, url, reason) from reason  # type: ignore[arg-type]
    ^^^^^^^^^^^^^^^^^^^^^^^^^^^^^^^^^^^^^^^^^^^^^^^^^^^
urllib3.exceptions.MaxRetryError: HTTPConnectionPool(host='127.0.0.1', port=5000): Max retries exceeded with url: /check_send_status (Caused by NewConnectionError('<urllib3.connection.HTTPConnection object at 0x7f724cef4f80>: Failed to establish a new connection: [Errno 111] Connection refused'))

During handling of the above exception, another exception occurred:

Traceback (most recent call last):
  File "/home/airflow/.local/lib/python3.12/site-packages/airflow/models/taskinstance.py", line 465, in _execute_task
    result = _execute_callable(context=context, **execute_callable_kwargs)
             ^^^^^^^^^^^^^^^^^^^^^^^^^^^^^^^^^^^^^^^^^^^^^^^^^^^^^^^^^^^^^
  File "/home/airflow/.local/lib/python3.12/site-packages/airflow/models/taskinstance.py", line 432, in _execute_callable
    return execute_callable(context=context, **execute_callable_kwargs)
           ^^^^^^^^^^^^^^^^^^^^^^^^^^^^^^^^^^^^^^^^^^^^^^^^^^^^^^^^^^^^
  File "/home/airflow/.local/lib/python3.12/site-packages/airflow/models/baseoperator.py", line 400, in wrapper
    return func(self, *args, **kwargs)
           ^^^^^^^^^^^^^^^^^^^^^^^^^^^
  File "/home/airflow/.local/lib/python3.12/site-packages/airflow/operators/python.py", line 235, in execute
    return_value = self.execute_callable()
                   ^^^^^^^^^^^^^^^^^^^^^^^
  File "/home/airflow/.local/lib/python3.12/site-packages/airflow/operators/python.py", line 252, in execute_callable
    return self.python_callable(*self.op_args, **self.op_kwargs)
           ^^^^^^^^^^^^^^^^^^^^^^^^^^^^^^^^^^^^^^^^^^^^^^^^^^^^^
  File "/opt/airflow/dags/check_send_status_dag.py", line 10, in check_send_status
    response = requests.get("http://127.0.0.1:5000/check_send_status")
               ^^^^^^^^^^^^^^^^^^^^^^^^^^^^^^^^^^^^^^^^^^^^^^^^^^^^^^^
  File "/home/airflow/.local/lib/python3.12/site-packages/requests/api.py", line 73, in get
    return request("get", url, params=params, **kwargs)
           ^^^^^^^^^^^^^^^^^^^^^^^^^^^^^^^^^^^^^^^^^^^^
  File "/home/airflow/.local/lib/python3.12/site-packages/requests/api.py", line 59, in request
    return session.request(method=method, url=url, **kwargs)
           ^^^^^^^^^^^^^^^^^^^^^^^^^^^^^^^^^^^^^^^^^^^^^^^^^
  File "/home/airflow/.local/lib/python3.12/site-packages/requests/sessions.py", line 589, in request
    resp = self.send(prep, **send_kwargs)
           ^^^^^^^^^^^^^^^^^^^^^^^^^^^^^^
  File "/home/airflow/.local/lib/python3.12/site-packages/requests/sessions.py", line 703, in send
    r = adapter.send(request, **kwargs)
        ^^^^^^^^^^^^^^^^^^^^^^^^^^^^^^^
  File "/home/airflow/.local/lib/python3.12/site-packages/requests/adapters.py", line 519, in send
    raise ConnectionError(e, request=request)
requests.exceptions.ConnectionError: HTTPConnectionPool(host='127.0.0.1', port=5000): Max retries exceeded with url: /check_send_status (Caused by NewConnectionError('<urllib3.connection.HTTPConnection object at 0x7f724cef4f80>: Failed to establish a new connection: [Errno 111] Connection refused'))
[2024-05-29T10:42:49.259+0000] {taskinstance.py:1206} INFO - Marking task as UP_FOR_RETRY. dag_id=check_send_status_dag, task_id=check_status, run_id=scheduled__2023-01-01T00:10:00+00:00, execution_date=20230101T001000, start_date=20240529T104248, end_date=20240529T104249
[2024-05-29T10:42:49.306+0000] {standard_task_runner.py:110} ERROR - Failed to execute job 9 for task check_status (HTTPConnectionPool(host='127.0.0.1', port=5000): Max retries exceeded with url: /check_send_status (Caused by NewConnectionError('<urllib3.connection.HTTPConnection object at 0x7f724cef4f80>: Failed to establish a new connection: [Errno 111] Connection refused')); 77)
[2024-05-29T10:42:49.347+0000] {local_task_job_runner.py:240} INFO - Task exited with return code 1
[2024-05-29T10:42:49.397+0000] {taskinstance.py:3498} INFO - 0 downstream tasks scheduled from follow-on schedule check
[2024-05-29T10:42:49.433+0000] {local_task_job_runner.py:222} INFO - ::endgroup::
[2024-05-29T13:53:54.539+0000] {local_task_job_runner.py:120} INFO - ::group::Pre task execution logs
[2024-05-29T13:53:54.590+0000] {taskinstance.py:2076} INFO - Dependencies all met for dep_context=non-requeueable deps ti=<TaskInstance: check_send_status_dag.check_status scheduled__2023-01-01T00:10:00+00:00 [queued]>
[2024-05-29T13:53:54.612+0000] {taskinstance.py:2076} INFO - Dependencies all met for dep_context=requeueable deps ti=<TaskInstance: check_send_status_dag.check_status scheduled__2023-01-01T00:10:00+00:00 [queued]>
[2024-05-29T13:53:54.613+0000] {taskinstance.py:2306} INFO - Starting attempt 1 of 2
[2024-05-29T13:53:54.735+0000] {taskinstance.py:2330} INFO - Executing <Task(PythonOperator): check_status> on 2023-01-01 00:10:00+00:00
[2024-05-29T13:53:54.748+0000] {standard_task_runner.py:63} INFO - Started process 1118 to run task
[2024-05-29T13:53:54.760+0000] {standard_task_runner.py:90} INFO - Running: ['airflow', 'tasks', 'run', 'check_send_status_dag', 'check_status', 'scheduled__2023-01-01T00:10:00+00:00', '--job-id', '9', '--raw', '--subdir', 'DAGS_FOLDER/check_send_status_dag.py', '--cfg-path', '/tmp/tmpdrg81urs']
[2024-05-29T13:53:54.768+0000] {standard_task_runner.py:91} INFO - Job 9: Subtask check_status
[2024-05-29T13:53:55.062+0000] {task_command.py:426} INFO - Running <TaskInstance: check_send_status_dag.check_status scheduled__2023-01-01T00:10:00+00:00 [running]> on host f708138922bb
[2024-05-29T13:53:55.293+0000] {taskinstance.py:2648} INFO - Exporting env vars: AIRFLOW_CTX_DAG_OWNER='airflow' AIRFLOW_CTX_DAG_ID='check_send_status_dag' AIRFLOW_CTX_TASK_ID='check_status' AIRFLOW_CTX_EXECUTION_DATE='2023-01-01T00:10:00+00:00' AIRFLOW_CTX_TRY_NUMBER='1' AIRFLOW_CTX_DAG_RUN_ID='scheduled__2023-01-01T00:10:00+00:00'
[2024-05-29T13:53:55.294+0000] {taskinstance.py:430} INFO - ::endgroup::
[2024-05-29T13:53:55.327+0000] {check_send_status_dag.py:15} ERROR - Error fetching status: 500 Server Error: INTERNAL SERVER ERROR for url: http://flask:5000/check_send_status
[2024-05-29T13:53:55.329+0000] {taskinstance.py:441} INFO - ::group::Post task execution logs
[2024-05-29T13:53:55.331+0000] {taskinstance.py:2905} ERROR - Task failed with exception
Traceback (most recent call last):
  File "/home/airflow/.local/lib/python3.12/site-packages/airflow/models/taskinstance.py", line 465, in _execute_task
    result = _execute_callable(context=context, **execute_callable_kwargs)
             ^^^^^^^^^^^^^^^^^^^^^^^^^^^^^^^^^^^^^^^^^^^^^^^^^^^^^^^^^^^^^
  File "/home/airflow/.local/lib/python3.12/site-packages/airflow/models/taskinstance.py", line 432, in _execute_callable
    return execute_callable(context=context, **execute_callable_kwargs)
           ^^^^^^^^^^^^^^^^^^^^^^^^^^^^^^^^^^^^^^^^^^^^^^^^^^^^^^^^^^^^
  File "/home/airflow/.local/lib/python3.12/site-packages/airflow/models/baseoperator.py", line 400, in wrapper
    return func(self, *args, **kwargs)
           ^^^^^^^^^^^^^^^^^^^^^^^^^^^
  File "/home/airflow/.local/lib/python3.12/site-packages/airflow/operators/python.py", line 235, in execute
    return_value = self.execute_callable()
                   ^^^^^^^^^^^^^^^^^^^^^^^
  File "/home/airflow/.local/lib/python3.12/site-packages/airflow/operators/python.py", line 252, in execute_callable
    return self.python_callable(*self.op_args, **self.op_kwargs)
           ^^^^^^^^^^^^^^^^^^^^^^^^^^^^^^^^^^^^^^^^^^^^^^^^^^^^^
  File "/opt/airflow/dags/check_send_status_dag.py", line 11, in check_send_status
    response.raise_for_status()
  File "/home/airflow/.local/lib/python3.12/site-packages/requests/models.py", line 1021, in raise_for_status
    raise HTTPError(http_error_msg, response=self)
requests.exceptions.HTTPError: 500 Server Error: INTERNAL SERVER ERROR for url: http://flask:5000/check_send_status
[2024-05-29T13:53:55.379+0000] {taskinstance.py:1206} INFO - Marking task as UP_FOR_RETRY. dag_id=check_send_status_dag, task_id=check_status, run_id=scheduled__2023-01-01T00:10:00+00:00, execution_date=20230101T001000, start_date=20240529T135354, end_date=20240529T135355
[2024-05-29T13:53:55.571+0000] {standard_task_runner.py:110} ERROR - Failed to execute job 9 for task check_status (500 Server Error: INTERNAL SERVER ERROR for url: http://flask:5000/check_send_status; 1118)
[2024-05-29T13:53:55.616+0000] {local_task_job_runner.py:240} INFO - Task exited with return code 1
[2024-05-29T13:53:55.714+0000] {taskinstance.py:3498} INFO - 0 downstream tasks scheduled from follow-on schedule check
[2024-05-29T13:53:55.723+0000] {local_task_job_runner.py:222} INFO - ::endgroup::
[2024-05-29T13:57:09.792+0000] {local_task_job_runner.py:120} INFO - ::group::Pre task execution logs
[2024-05-29T13:57:09.844+0000] {taskinstance.py:2076} INFO - Dependencies all met for dep_context=non-requeueable deps ti=<TaskInstance: check_send_status_dag.check_status scheduled__2023-01-01T00:10:00+00:00 [queued]>
[2024-05-29T13:57:09.868+0000] {taskinstance.py:2076} INFO - Dependencies all met for dep_context=requeueable deps ti=<TaskInstance: check_send_status_dag.check_status scheduled__2023-01-01T00:10:00+00:00 [queued]>
[2024-05-29T13:57:09.868+0000] {taskinstance.py:2306} INFO - Starting attempt 1 of 2
[2024-05-29T13:57:09.972+0000] {taskinstance.py:2330} INFO - Executing <Task(PythonOperator): check_status> on 2023-01-01 00:10:00+00:00
[2024-05-29T13:57:09.979+0000] {standard_task_runner.py:63} INFO - Started process 1158 to run task
[2024-05-29T13:57:09.983+0000] {standard_task_runner.py:90} INFO - Running: ['airflow', 'tasks', 'run', 'check_send_status_dag', 'check_status', 'scheduled__2023-01-01T00:10:00+00:00', '--job-id', '9', '--raw', '--subdir', 'DAGS_FOLDER/check_send_status_dag.py', '--cfg-path', '/tmp/tmpflugy5_w']
[2024-05-29T13:57:09.986+0000] {standard_task_runner.py:91} INFO - Job 9: Subtask check_status
[2024-05-29T13:57:10.133+0000] {task_command.py:426} INFO - Running <TaskInstance: check_send_status_dag.check_status scheduled__2023-01-01T00:10:00+00:00 [running]> on host f708138922bb
[2024-05-29T13:57:10.398+0000] {taskinstance.py:2648} INFO - Exporting env vars: AIRFLOW_CTX_DAG_OWNER='airflow' AIRFLOW_CTX_DAG_ID='check_send_status_dag' AIRFLOW_CTX_TASK_ID='check_status' AIRFLOW_CTX_EXECUTION_DATE='2023-01-01T00:10:00+00:00' AIRFLOW_CTX_TRY_NUMBER='1' AIRFLOW_CTX_DAG_RUN_ID='scheduled__2023-01-01T00:10:00+00:00'
[2024-05-29T13:57:10.400+0000] {taskinstance.py:430} INFO - ::endgroup::
[2024-05-29T13:57:10.440+0000] {check_send_status_dag.py:15} ERROR - Error fetching status: 500 Server Error: INTERNAL SERVER ERROR for url: http://flask:5000/check_send_status
[2024-05-29T13:57:10.442+0000] {taskinstance.py:441} INFO - ::group::Post task execution logs
[2024-05-29T13:57:10.443+0000] {taskinstance.py:2905} ERROR - Task failed with exception
Traceback (most recent call last):
  File "/home/airflow/.local/lib/python3.12/site-packages/airflow/models/taskinstance.py", line 465, in _execute_task
    result = _execute_callable(context=context, **execute_callable_kwargs)
             ^^^^^^^^^^^^^^^^^^^^^^^^^^^^^^^^^^^^^^^^^^^^^^^^^^^^^^^^^^^^^
  File "/home/airflow/.local/lib/python3.12/site-packages/airflow/models/taskinstance.py", line 432, in _execute_callable
    return execute_callable(context=context, **execute_callable_kwargs)
           ^^^^^^^^^^^^^^^^^^^^^^^^^^^^^^^^^^^^^^^^^^^^^^^^^^^^^^^^^^^^
  File "/home/airflow/.local/lib/python3.12/site-packages/airflow/models/baseoperator.py", line 400, in wrapper
    return func(self, *args, **kwargs)
           ^^^^^^^^^^^^^^^^^^^^^^^^^^^
  File "/home/airflow/.local/lib/python3.12/site-packages/airflow/operators/python.py", line 235, in execute
    return_value = self.execute_callable()
                   ^^^^^^^^^^^^^^^^^^^^^^^
  File "/home/airflow/.local/lib/python3.12/site-packages/airflow/operators/python.py", line 252, in execute_callable
    return self.python_callable(*self.op_args, **self.op_kwargs)
           ^^^^^^^^^^^^^^^^^^^^^^^^^^^^^^^^^^^^^^^^^^^^^^^^^^^^^
  File "/opt/airflow/dags/check_send_status_dag.py", line 11, in check_send_status
    response.raise_for_status()
  File "/home/airflow/.local/lib/python3.12/site-packages/requests/models.py", line 1021, in raise_for_status
    raise HTTPError(http_error_msg, response=self)
requests.exceptions.HTTPError: 500 Server Error: INTERNAL SERVER ERROR for url: http://flask:5000/check_send_status
[2024-05-29T13:57:10.474+0000] {taskinstance.py:1206} INFO - Marking task as UP_FOR_RETRY. dag_id=check_send_status_dag, task_id=check_status, run_id=scheduled__2023-01-01T00:10:00+00:00, execution_date=20230101T001000, start_date=20240529T135709, end_date=20240529T135710
[2024-05-29T13:57:10.602+0000] {standard_task_runner.py:110} ERROR - Failed to execute job 9 for task check_status (500 Server Error: INTERNAL SERVER ERROR for url: http://flask:5000/check_send_status; 1158)
[2024-05-29T13:57:10.642+0000] {local_task_job_runner.py:240} INFO - Task exited with return code 1
[2024-05-29T13:57:10.704+0000] {taskinstance.py:3498} INFO - 0 downstream tasks scheduled from follow-on schedule check
[2024-05-29T13:57:10.709+0000] {local_task_job_runner.py:222} INFO - ::endgroup::
[2024-05-29T14:42:28.435+0000] {local_task_job_runner.py:120} INFO - ::group::Pre task execution logs
[2024-05-29T14:42:28.488+0000] {taskinstance.py:2076} INFO - Dependencies all met for dep_context=non-requeueable deps ti=<TaskInstance: check_send_status_dag.check_status scheduled__2023-01-01T00:10:00+00:00 [queued]>
[2024-05-29T14:42:28.511+0000] {taskinstance.py:2076} INFO - Dependencies all met for dep_context=requeueable deps ti=<TaskInstance: check_send_status_dag.check_status scheduled__2023-01-01T00:10:00+00:00 [queued]>
[2024-05-29T14:42:28.512+0000] {taskinstance.py:2306} INFO - Starting attempt 1 of 2
[2024-05-29T14:42:28.568+0000] {taskinstance.py:2330} INFO - Executing <Task(PythonOperator): check_status> on 2023-01-01 00:10:00+00:00
[2024-05-29T14:42:28.575+0000] {standard_task_runner.py:63} INFO - Started process 1571 to run task
[2024-05-29T14:42:28.578+0000] {standard_task_runner.py:90} INFO - Running: ['airflow', 'tasks', 'run', 'check_send_status_dag', 'check_status', 'scheduled__2023-01-01T00:10:00+00:00', '--job-id', '9', '--raw', '--subdir', 'DAGS_FOLDER/check_send_status_dag.py', '--cfg-path', '/tmp/tmpxq416trc']
[2024-05-29T14:42:28.581+0000] {standard_task_runner.py:91} INFO - Job 9: Subtask check_status
[2024-05-29T14:42:28.710+0000] {task_command.py:426} INFO - Running <TaskInstance: check_send_status_dag.check_status scheduled__2023-01-01T00:10:00+00:00 [running]> on host f708138922bb
[2024-05-29T14:42:28.913+0000] {taskinstance.py:2648} INFO - Exporting env vars: AIRFLOW_CTX_DAG_OWNER='airflow' AIRFLOW_CTX_DAG_ID='check_send_status_dag' AIRFLOW_CTX_TASK_ID='check_status' AIRFLOW_CTX_EXECUTION_DATE='2023-01-01T00:10:00+00:00' AIRFLOW_CTX_TRY_NUMBER='1' AIRFLOW_CTX_DAG_RUN_ID='scheduled__2023-01-01T00:10:00+00:00'
[2024-05-29T14:42:28.914+0000] {taskinstance.py:430} INFO - ::endgroup::
[2024-05-29T14:42:28.946+0000] {check_send_status_dag.py:13} INFO - Status: {'status': 'unknown'}
[2024-05-29T14:42:28.947+0000] {python.py:237} INFO - Done. Returned value was: None
[2024-05-29T14:42:28.948+0000] {taskinstance.py:441} INFO - ::group::Post task execution logs
[2024-05-29T14:42:28.996+0000] {taskinstance.py:1206} INFO - Marking task as SUCCESS. dag_id=check_send_status_dag, task_id=check_status, run_id=scheduled__2023-01-01T00:10:00+00:00, execution_date=20230101T001000, start_date=20240529T144228, end_date=20240529T144228
[2024-05-29T14:42:29.073+0000] {local_task_job_runner.py:240} INFO - Task exited with return code 0
[2024-05-29T14:42:29.107+0000] {taskinstance.py:3498} INFO - 0 downstream tasks scheduled from follow-on schedule check
[2024-05-29T14:42:29.111+0000] {local_task_job_runner.py:222} INFO - ::endgroup::
